Workbook
Name __DAT1: #REF!
Name __DAT1: #REF!
Name __DAT1: #REF!
Name __DAT10: #REF!
Name __DAT10: #REF!
Name __DAT10: #REF!
Name __DAT11: #REF!
Name __DAT11: #REF!
Name __DAT11: #REF!
Name __DAT12: #REF!
Name __DAT12: #REF!
Name __DAT12: #REF!
Name __DAT13: #REF!
Name __DAT13: #REF!
Name __DAT13: #REF!
Name __DAT14: #REF!
Name __DAT14: #REF!
Name __DAT14: #REF!
Name __DAT15: #REF!
Name __DAT15: #REF!
Name __DAT15: #REF!
Name __DAT16: #REF!
Name __DAT16: #REF!
Name __DAT16: #REF!
Name __DAT17: #REF!
Name __DAT17: #REF!
Name __DAT17: #REF!
Name __DAT18: #REF!
Name __DAT18: #REF!
Name __DAT18: #REF!
Name __DAT19: #REF!
Name __DAT19: #REF!
Name __DAT19: #REF!
Name __DAT2: #REF!
Name __DAT2: #REF!
Name __DAT2: #REF!
Name __DAT20: #REF!
Name __DAT20: #REF!
Name __DAT20: #REF!
Name __DAT21: #REF!
Name __DAT21: #REF!
Name __DAT21: #REF!
Name __DAT3: #REF!
Name __DAT3: #REF!
Name __DAT3: #REF!
Name __DAT4: #REF!
Name __DAT4: #REF!
Name __DAT4: #REF!
Name __DAT5: #REF!
Name __DAT5: #REF!
Name __DAT5: #REF!
Name __DAT6: #REF!
Name __DAT6: #REF!
Name __DAT6: #REF!
Name __DAT7: #REF!
Name __DAT7: #REF!
Name __DAT7: #REF!
Name __DAT8: #REF!
Name __DAT8: #REF!
Name __DAT8: #REF!

Sheet MATRIZ
B2: MATRIZ DE PRIORIDADE
G3: =IFERROR(VLOOKUP(C3,#REF!,4,FALSE),"") | H3: =VLOOKUP(C3,Dados!B:AW,10,0) -> #N/A | I3: =(VLOOKUP(C3,Dados!B:AW,47,0)) -> #N/A | K3: =IFERROR((VLOOKUP(C3,Dados!B:AW,43,0)),0) -> 0 | L3: =IFERROR((VLOOKUP(C3,Dados!B:AW,44,0)),0) -> 0 | M3: =IFERROR((VLOOKUP(C3,Dados!B:AW,42,0)),0) -> 0 | N3: =IFERROR((VLOOKUP(C3,Dados!B:AW,46,0)),0) -> 0 | O3: =IF(AND(J3="Parcial",N3>0,H3>1),-1,IF(AND(J3="Parcial",N3>0,H3<1.1),1,IF(AND(J3="Parcial",N3<0,H3>1.09),-1,IF(J3="Total",-1,IF(H3>1.09,1,2))))) -> #N/A
B4: ID | C4: TAG | D4: Mini Fábrica | E4: Célula | F4: Denominação | I4: Obsolescência | K4: Custos Projetados | L4: (7 anos) | N4: LCC | AB4: -1 | AC4: =COUNTIF($AC$7:$AC$540,$AB4) -> 132 | AD4: =COUNTIF($AD$7:$AD$540,$AB4) -> 127 | AE4: =COUNTIF($AE$7:$AE$540,$AB4) -> 127
G5: β (2022) | H5: β (atual) | I5: Comportamento das Falhas | J5: Situação | K5: Atual | L5: Novo | M5: Potencial Ganho (7 Anos) | N5: ROI | O5: Farol | T5: Priorizar | V5: RISK MANAGEMENT | AB5: 1 | AC5: =COUNTIF($AC$7:$AC$540,$AB5) -> 2 | AD5: =COUNTIF($AD$7:$AD$540,$AB5) -> 2 | AE5: =COUNTIF($AE$7:$AE$540,$AB5) -> 162 | AH5: MOD012 | AI5: =CONCATENATE(AH5,"*") -> MOD012*
B6: 293 | C6: EMP123 | D6: UMO | E6: - | F6: EMP123-EMPILHADEIRA HIDRÁULICA MANUAL | G6: =IFERROR(VLOOKUP(C6,#REF!,4,FALSE),"") | H6: =VLOOKUP(C6,Dados!B:AW,11,0) -> 0 | I6: =(VLOOKUP(C6,Dados!B:AW,48,0)) -> Confiabilidade em Crescimento | J6: Em análise | K6: =IFERROR((VLOOKUP(C6,Dados!B:AW,44,0)),0) -> 0 | L6: =IFERROR((VLOOKUP(C6,Dados!B:AW,45,0)),0) -> 0 | M6: =IFERROR((VLOOKUP(C6,Dados!B:AW,43,0)),0) -> 0 | N6: =IFERROR((VLOOKUP(C6,Dados!B:AW,47,0)),0) -> 0 | O6: =IF(AND(J6="Parcial",N6>0,H6>1),-1,IF(AND(J6="Parcial",N6>0,H6<1.1),1,IF(AND(J6="Parcial",N6<0,H6>1.09),-1,IF(J6="Total",-1,IF(H6>1.09,1,2))))) -> 2 | P6: =IF(G6="",0,IF(H6>G6,-1,1)) -> 0 | S6: -1 | T6: Substituir | AB6: 2 | AC6: =COUNTIF($AC$7:$AC$540,$AB6) -> 399 | AD6: =COUNTIF($AD$7:$AD$540,$AB6) -> 404 | AE6: =COUNTIF($AE$7:$AE$540,$AB6) -> 244 | AH6: ROB040 | AI6: =CONCATENATE(AH6,"*") -> ROB040*
B7: 328 | C7: FOR083 | D7: ZCP | E7: - | F7: FOR083-FORNO CONTÍNUO | G7: =IFERROR(VLOOKUP(C7,#REF!,4,FALSE),"") | H7: =VLOOKUP(C7,Dados!B:AW,11,0) -> 0.77 | I7: =(VLOOKUP(C7,Dados!B:AW,48,0)) -> Confiabilidade em Crescimento | J7: Em análise | K7: =IFERROR((VLOOKUP(C7,Dados!B:AW,44,0)),0) -> 0 | L7: =IFERROR((VLOOKUP(C7,Dados!B:AW,45,0)),0) -> 0 | M7: =IFERROR((VLOOKUP(C7,Dados!B:AW,43,0)),0) -> 0 | N7: =IFERROR((VLOOKUP(C7,Dados!B:AW,47,0)),0) -> 0 | O7: =IF(AND(J7="Parcial",N7>0,H7>1),-1,IF(AND(J7="Parcial",N7>0,H7<1.1),1,IF(AND(J7="Parcial",N7<0,H7>1.09),-1,IF(J7="Total",-1,IF(H7>1.09,1,2))))) -> 2 | P7: =IF(G7="",0,IF(H7>G7,-1,1)) -> 0 | S7: 1 | T7: Acompanhar | AC7: -1 | AD7: -1 | AE7: -1 | AH7: ROB038 | AI7: =CONCATENATE(AH7,"*") -> ROB038*
B8: 17 | C8: BRU024 | D8: ZCP | E8: BRUC01 | F8: BRU024-BRUNIDORA | G8: =IFERROR(VLOOKUP(C8,#REF!,4,FALSE),"") | H8: =VLOOKUP(C8,Dados!B:AW,11,0) -> 1.64 | I8: =(VLOOKUP(C8,Dados!B:AW,48,0)) -> Fase de Degradação | J8: Total | K8: =IFERROR((VLOOKUP(C8,Dados!B:AW,44,0)),0) -> 0 | L8: =IFERROR((VLOOKUP(C8,Dados!B:AW,45,0)),0) -> 0 | M8: =IFERROR((VLOOKUP(C8,Dados!B:AW,43,0)),0) -> 0 | N8: =IFERROR((VLOOKUP(C8,Dados!B:AW,47,0)),0) -> 0 | O8: =IF(AND(J8="Parcial",N8>0,H8>1),-1,IF(AND(J8="Parcial",N8>0,H8<1.1),1,IF(AND(J8="Parcial",N8<0,H8>1.09),-1,IF(J8="Total",-1,IF(H8>1.09,1,2))))) -> -1 | P8: =IF(G8="",0,IF(H8>G8,-1,1)) -> 0 | S8: 2 | T8: Manter | AC8: 2 | AD8: 2 | AE8: 2 | AH8: PON008 | AI8: =CONCATENATE(AH8,"*") -> PON008*
B9: 19 | C9: BRU026 | D9: ZCP | E9: BRUC01 | F9: BRU026-BRUNIDORA | G9: =IFERROR(VLOOKUP(C9,#REF!,4,FALSE),"") | H9: =VLOOKUP(C9,Dados!B:AW,11,0) -> 1.19 | I9: =(VLOOKUP(C9,Dados!B:AW,48,0)) -> Fase de Degradação | J9: Total | K9: =IFERROR((VLOOKUP(C9,Dados!B:AW,44,0)),0) -> 0 | L9: =IFERROR((VLOOKUP(C9,Dados!B:AW,45,0)),0) -> 0 | M9: =IFERROR((VLOOKUP(C9,Dados!B:AW,43,0)),0) -> 0 | N9: =IFERROR((VLOOKUP(C9,Dados!B:AW,47,0)),0) -> 0 | O9: =IF(AND(J9="Parcial",N9>0,H9>1),-1,IF(AND(J9="Parcial",N9>0,H9<1.1),1,IF(AND(J9="Parcial",N9<0,H9>1.09),-1,IF(J9="Total",-1,IF(H9>1.09,1,2))))) -> -1 | P9: =IF(G9="",0,IF(H9>G9,-1,1)) -> 0 | AC9: 2 | AD9: 2 | AE9: 1 | AH9: GRV012 | AI9: =CONCATENATE(AH9,"*") -> GRV012*
B10: 11 | C10: BRU008 | D10: ZCP | E10: BRUC02 | F10: =VLOOKUP(C10,[9]Dados!B:C,2,0) -> BRU008-BRUNIDORA | G10: =IFERROR(VLOOKUP(C10,#REF!,4,FALSE),"") | H10: =VLOOKUP(C10,Dados!B:AW,11,0) -> 0.95 | I10: =(VLOOKUP(C10,Dados!B:AW,48,0)) -> Confiabilidade em Crescimento | J10: Não há | K10: =IFERROR((VLOOKUP(C10,Dados!B:AW,44,0)),0) -> 0 | L10: =IFERROR((VLOOKUP(C10,Dados!B:AW,45,0)),0) -> 0 | M10: =IFERROR((VLOOKUP(C10,Dados!B:AW,43,0)),0) -> 0 | N10: =IFERROR((VLOOKUP(C10,Dados!B:AW,47,0)),0) -> 0 | O10: =IF(AND(J10="Parcial",N10>0,H10>1),-1,IF(AND(J10="Parcial",N10>0,H10<1.1),1,IF(AND(J10="Parcial",N10<0,H10>1.09),-1,IF(J10="Total",-1,IF(H10>1.09,1,2))))) -> 2 | P10: =IF(G10="",0,IF(H10>G10,-1,1)) -> 0 | AC10: 2 | AD10: 2 | AE10: 1 | AH10: ROB007 | AI10: =CONCATENATE(AH10,"*") -> ROB007*
B11: 65 | C11: BRU072 | D11: ZCP | E11: BRUC02 | F11: BRU072-BRUNIDORA | G11: =IFERROR(VLOOKUP(C11,#REF!,4,FALSE),"") | H11: =VLOOKUP(C11,Dados!B:AW,11,0) -> 0.99 | I11: =(VLOOKUP(C11,Dados!B:AW,48,0)) -> Confiabilidade em Crescimento | K11: =IFERROR((VLOOKUP(C11,Dados!B:AW,44,0)),0) -> 0 | L11: =IFERROR((VLOOKUP(C11,Dados!B:AW,45,0)),0) -> 0 | M11: =IFERROR((VLOOKUP(C11,Dados!B:AW,43,0)),0) -> 0 | N11: =IFERROR((VLOOKUP(C11,Dados!B:AW,47,0)),0) -> 0 | O11: =IF(AND(J11="Parcial",N11>0,H11>1),-1,IF(AND(J11="Parcial",N11>0,H11<1.1),1,IF(AND(J11="Parcial",N11<0,H11>1.09),-1,IF(J11="Total",-1,IF(H11>1.09,1,2))))) -> 2 | P11: =IF(G11="",0,IF(H11>G11,-1,1)) -> 0 | AC11: 2 | AD11: 2 | AE11: 2 | AH11: EST127 | AI11: =CONCATENATE(AH11,"*") -> EST127*
B12: 16 | C12: BRU014 | D12: ZCP | E12: BRUC04 | F12: =VLOOKUP(C12,[9]Dados!B:C,2,0) -> BRU014-BRUNIDORA | G12: =IFERROR(VLOOKUP(C12,#REF!,4,FALSE),"") | H12: =VLOOKUP(C12,Dados!B:AW,11,0) -> 1.39 | I12: =(VLOOKUP(C12,Dados!B:AW,48,0)) -> Fase de Degradação | J12: Não há | K12: =IFERROR((VLOOKUP(C12,Dados!B:AW,44,0)),0) -> 0 | L12: =IFERROR((VLOOKUP(C12,Dados!B:AW,45,0)),0) -> 0 | M12: =IFERROR((VLOOKUP(C12,Dados!B:AW,43,0)),0) -> 0 | N12: =IFERROR((VLOOKUP(C12,Dados!B:AW,47,0)),0) -> 0 | O12: =IF(AND(J12="Parcial",N12>0,H12>1),-1,IF(AND(J12="Parcial",N12>0,H12<1.1),1,IF(AND(J12="Parcial",N12<0,H12>1.09),-1,IF(J12="Total",-1,IF(H12>1.09,1,2))))) -> 1 | P12: =IF(G12="",0,IF(H12>G12,-1,1)) -> 0 | AC12: 2 | AD12: 2 | AE12: 2 | AH12: TAN042 | AI12: =CONCATENATE(AH12,"*") -> TAN042*
B13: 55 | C13: BRU062 | D13: ZCP | E13: BRUC04 | F13: BRU062-BRUNIDORA | G13: =IFERROR(VLOOKUP(C13,#REF!,4,FALSE),"") | H13: =VLOOKUP(C13,Dados!B:AW,11,0) -> 1.2 | I13: =(VLOOKUP(C13,Dados!B:AW,48,0)) -> Fase de Degradação | K13: =IFERROR((VLOOKUP(C13,Dados!B:AW,44,0)),0) -> 0 | L13: =IFERROR((VLOOKUP(C13,Dados!B:AW,45,0)),0) -> 0 | M13: =IFERROR((VLOOKUP(C13,Dados!B:AW,43,0)),0) -> 0 | N13: =IFERROR((VLOOKUP(C13,Dados!B:AW,47,0)),0) -> 0 | O13: =IF(AND(J13="Parcial",N13>0,H13>1),-1,IF(AND(J13="Parcial",N13>0,H13<1.1),1,IF(AND(J13="Parcial",N13<0,H13>1.09),-1,IF(J13="Total",-1,IF(H13>1.09,1,2))))) -> 1 | P13: =IF(G13="",0,IF(H13>G13,-1,1)) -> 0 | AC13: -1 | AD13: -1 | AE13: -1 | AH13: BRU037 | AI13: =CONCATENATE(AH13,"*") -> BRU037*
B14: 15 | C14: BRU012 | D14: ZCP | E14: BRUC05 | F14: =VLOOKUP(C14,[9]Dados!B:C,2,0) -> BRU012-BRUNIDORA | G14: =IFERROR(VLOOKUP(C14,#REF!,4,FALSE),"") | H14: =VLOOKUP(C14,Dados!B:AW,11,0) -> 1.36 | I14: =(VLOOKUP(C14,Dados!B:AW,48,0)) -> Fase de Degradação | J14: Não há | K14: =IFERROR((VLOOKUP(C14,Dados!B:AW,44,0)),0) -> 0 | L14: =IFERROR((VLOOKUP(C14,Dados!B:AW,45,0)),0) -> 0 | M14: =IFERROR((VLOOKUP(C14,Dados!B:AW,43,0)),0) -> 0 | N14: =IFERROR((VLOOKUP(C14,Dados!B:AW,47,0)),0) -> 0 | O14: =IF(AND(J14="Parcial",N14>0,H14>1),-1,IF(AND(J14="Parcial",N14>0,H14<1.1),1,IF(AND(J14="Parcial",N14<0,H14>1.09),-1,IF(J14="Total",-1,IF(H14>1.09,1,2))))) -> 1 | P14: =IF(G14="",0,IF(H14>G14,-1,1)) -> 0 | AC14: -1 | AD14: -1 | AE14: -1 | AH14: BRU039 | AI14: =CONCATENATE(AH14,"*") -> BRU039*
B15: 18 | C15: BRU025 | D15: ZCP | E15: BRUC05 | F15: =VLOOKUP(C15,[9]Dados!B:C,2,0) -> BRU025-BRUNIDORA | G15: =IFERROR(VLOOKUP(C15,#REF!,4,FALSE),"") | H15: =VLOOKUP(C15,Dados!B:AW,11,0) -> 0.93 | I15: =(VLOOKUP(C15,Dados!B:AW,48,0)) -> Confiabilidade em Crescimento | J15: Não há | K15: =IFERROR((VLOOKUP(C15,Dados!B:AW,44,0)),0) -> 0 | L15: =IFERROR((VLOOKUP(C15,Dados!B:AW,45,0)),0) -> 0 | M15: =IFERROR((VLOOKUP(C15,Dados!B:AW,43,0)),0) -> 0 | N15: =IFERROR((VLOOKUP(C15,Dados!B:AW,47,0)),0) -> 0 | O15: =IF(AND(J15="Parcial",N15>0,H15>1),-1,IF(AND(J15="Parcial",N15>0,H15<1.1),1,IF(AND(J15="Parcial",N15<0,H15>1.09),-1,IF(J15="Total",-1,IF(H15>1.09,1,2))))) -> 2 | P15: =IF(G15="",0,IF(H15>G15,-1,1)) -> 0 | AC15: -1 | AD15: -1 | AE15: -1 | AH15: ROB066 | AI15: =CONCATENATE(AH15,"*") -> ROB066*
B16: 52 | C16: BRU059 | D16: ZCP | E16: BRUC05 | F16: BRU059-BRUNIDORA | G16: =IFERROR(VLOOKUP(C16,#REF!,4,FALSE),"") | H16: =VLOOKUP(C16,Dados!B:AW,11,0) -> 0.48 | I16: =(VLOOKUP(C16,Dados!B:AW,48,0)) -> Confiabilidade em Crescimento | K16: =IFERROR((VLOOKUP(C16,Dados!B:AW,44,0)),0) -> 0 | L16: =IFERROR((VLOOKUP(C16,Dados!B:AW,45,0)),0) -> 0 | M16: =IFERROR((VLOOKUP(C16,Dados!B:AW,43,0)),0) -> 0 | N16: =IFERROR((VLOOKUP(C16,Dados!B:AW,47,0)),0) -> 0 | O16: =IF(AND(J16="Parcial",N16>0,H16>1),-1,IF(AND(J16="Parcial",N16>0,H16<1.1),1,IF(AND(J16="Parcial",N16<0,H16>1.09),-1,IF(J16="Total",-1,IF(H16>1.09,1,2))))) -> 2 | P16: =IF(G16="",0,IF(H16>G16,-1,1)) -> 0 | AC16: 2 | AD16: 2 | AE16: 2 | AH16: ROB042 | AI16: =CONCATENATE(AH16,"*") -> ROB042*
B17: 26 | C17: BRU033 | D17: ZCP | E17: BRUC06 | F17: =VLOOKUP(C17,[9]Dados!B:C,2,0) -> BRU033-BRUNIDORA | G17: =IFERROR(VLOOKUP(C17,#REF!,4,FALSE),"") | H17: =VLOOKUP(C17,Dados!B:AW,11,0) -> 1.26 | I17: =(VLOOKUP(C17,Dados!B:AW,48,0)) -> Fase de Degradação | J17: Não há | K17: =IFERROR((VLOOKUP(C17,Dados!B:AW,44,0)),0) -> 0 | L17: =IFERROR((VLOOKUP(C17,Dados!B:AW,45,0)),0) -> 0 | M17: =IFERROR((VLOOKUP(C17,Dados!B:AW,43,0)),0) -> 0 | N17: =IFERROR((VLOOKUP(C17,Dados!B:AW,47,0)),0) -> 0 | O17: =IF(AND(J17="Parcial",N17>0,H17>1),-1,IF(AND(J17="Parcial",N17>0,H17<1.1),1,IF(AND(J17="Parcial",N17<0,H17>1.09),-1,IF(J17="Total",-1,IF(H17>1.09,1,2))))) -> 1 | P17: =IF(G17="",0,IF(H17>G17,-1,1)) -> 0 | AC17: 2 | AD17: 2 | AE17: 2 | AH17: ELE008 | AI17: =CONCATENATE(AH17,"*") -> ELE008*
B18: 27 | C18: BRU034 | D18: ZCP | E18: BRUC06 | F18: =VLOOKUP(C18,[9]Dados!B:C,2,0) -> BRU034-BRUNIDORA | G18: =IFERROR(VLOOKUP(C18,#REF!,4,FALSE),"") | H18: =VLOOKUP(C18,Dados!B:AW,11,0) -> 1.56 | I18: =(VLOOKUP(C18,Dados!B:AW,48,0)) -> Fase de Degradação | J18: Total | K18: =IFERROR((VLOOKUP(C18,Dados!B:AW,44,0)),0) -> 0 | L18: =IFERROR((VLOOKUP(C18,Dados!B:AW,45,0)),0) -> 0 | M18: =IFERROR((VLOOKUP(C18,Dados!B:AW,43,0)),0) -> 0 | N18: =IFERROR((VLOOKUP(C18,Dados!B:AW,47,0)),0) -> 0 | O18: =IF(AND(J18="Parcial",N18>0,H18>1),-1,IF(AND(J18="Parcial",N18>0,H18<1.1),1,IF(AND(J18="Parcial",N18<0,H18>1.09),-1,IF(J18="Total",-1,IF(H18>1.09,1,2))))) -> -1 | P18: =IF(G18="",0,IF(H18>G18,-1,1)) -> 0 | AC18: -1 | AD18: -1 | AE18: -1 | AH18: ELE018 | AI18: =CONCATENATE(AH18,"*") -> ELE018*
B19: 20 | C19: BRU027 | D19: ZCP | E19: BRUC08 | F19: BRU027-BRUNIDORA | G19: =IFERROR(VLOOKUP(C19,#REF!,4,FALSE),"") | H19: =VLOOKUP(C19,Dados!B:AW,11,0) -> 1.62 | I19: =(VLOOKUP(C19,Dados!B:AW,48,0)) -> Fase de Degradação | J19: Não há | K19: =IFERROR((VLOOKUP(C19,Dados!B:AW,44,0)),0) -> 0 | L19: =IFERROR((VLOOKUP(C19,Dados!B:AW,45,0)),0) -> 0 | M19: =IFERROR((VLOOKUP(C19,Dados!B:AW,43,0)),0) -> 0 | N19: =IFERROR((VLOOKUP(C19,Dados!B:AW,47,0)),0) -> 0 | O19: =IF(AND(J19="Parcial",N19>0,H19>1),-1,IF(AND(J19="Parcial",N19>0,H19<1.1),1,IF(AND(J19="Parcial",N19<0,H19>1.09),-1,IF(J19="Total",-1,IF(H19>1.09,1,2))))) -> 1 | P19: =IF(G19="",0,IF(H19>G19,-1,1)) -> 0 | AC19: -1 | AD19: -1 | AE19: -1 | AH19: CEN043 | AI19: =CONCATENATE(AH19,"*") -> CEN043*
B20: 21 | C20: BRU028 | D20: ZCP | E20: BRUC08 | F20: =VLOOKUP(C20,[9]Dados!B:C,2,0) -> BRU028-BRUNIDORA | G20: =IFERROR(VLOOKUP(C20,#REF!,4,FALSE),"") | H20: =VLOOKUP(C20,Dados!B:AW,11,0) -> 1.43 | I20: =(VLOOKUP(C20,Dados!B:AW,48,0)) -> Fase de Degradação | J20: Total | K20: =IFERROR((VLOOKUP(C20,Dados!B:AW,44,0)),0) -> 0 | L20: =IFERROR((VLOOKUP(C20,Dados!B:AW,45,0)),0) -> 0 | M20: =IFERROR((VLOOKUP(C20,Dados!B:AW,43,0)),0) -> 0 | N20: =IFERROR((VLOOKUP(C20,Dados!B:AW,47,0)),0) -> 0 | O20: =IF(AND(J20="Parcial",N20>0,H20>1),-1,IF(AND(J20="Parcial",N20>0,H20<1.1),1,IF(AND(J20="Parcial",N20<0,H20>1.09),-1,IF(J20="Total",-1,IF(H20>1.09,1,2))))) -> -1 | P20: =IF(G20="",0,IF(H20>G20,-1,1)) -> 0 | AC20: 2 | AD20: 2 | AE20: 1 | AH20: JAT003 | AI20: =CONCATENATE(AH20,"*") -> JAT003*
B21: 22 | C21: BRU029 | D21: ZCP | E21: BRUC10 | F21: =VLOOKUP(C21,[9]Dados!B:C,2,0) -> BRU029-BRUNIDORA | G21: =IFERROR(VLOOKUP(C21,#REF!,4,FALSE),"") | H21: =VLOOKUP(C21,Dados!B:AW,11,0) -> 1.23 | I21: =(VLOOKUP(C21,Dados!B:AW,48,0)) -> Fase de Degradação | J21: Não há | K21: =IFERROR((VLOOKUP(C21,Dados!B:AW,44,0)),0) -> 0 | L21: =IFERROR((VLOOKUP(C21,Dados!B:AW,45,0)),0) -> 0 | M21: =IFERROR((VLOOKUP(C21,Dados!B:AW,43,0)),0) -> 0 | N21: =IFERROR((VLOOKUP(C21,Dados!B:AW,47,0)),0) -> 0 | O21: =IF(AND(J21="Parcial",N21>0,H21>1),-1,IF(AND(J21="Parcial",N21>0,H21<1.1),1,IF(AND(J21="Parcial",N21<0,H21>1.09),-1,IF(J21="Total",-1,IF(H21>1.09,1,2))))) -> 1 | P21: =IF(G21="",0,IF(H21>G21,-1,1)) -> 0 | AC21: -1 | AD21: -1 | AE21: -1 | AH21: BRU035 | AI21: =CONCATENATE(AH21,"*") -> BRU035*
B22: 23 | C22: BRU030 | D22: ZCP | E22: BRUC10 | F22: =VLOOKUP(C22,[9]Dados!B:C,2,0) -> BRU030-BRUNIDORA | G22: =IFERROR(VLOOKUP(C22,#REF!,4,FALSE),"") | H22: =VLOOKUP(C22,Dados!B:AW,11,0) -> 1.71 | I22: =(VLOOKUP(C22,Dados!B:AW,48,0)) -> Fase de Degradação | J22: Total | K22: =IFERROR((VLOOKUP(C22,Dados!B:AW,44,0)),0) -> 0 | L22: =IFERROR((VLOOKUP(C22,Dados!B:AW,45,0)),0) -> 0 | M22: =IFERROR((VLOOKUP(C22,Dados!B:AW,43,0)),0) -> 0 | N22: =IFERROR((VLOOKUP(C22,Dados!B:AW,47,0)),0) -> 0 | O22: =IF(AND(J22="Parcial",N22>0,H22>1),-1,IF(AND(J22="Parcial",N22>0,H22<1.1),1,IF(AND(J22="Parcial",N22<0,H22>1.09),-1,IF(J22="Total",-1,IF(H22>1.09,1,2))))) -> -1 | P22: =IF(G22="",0,IF(H22>G22,-1,1)) -> 0 | AC22: -1 | AD22: -1 | AE22: -1 | AH22: ROB006 | AI22: =CONCATENATE(AH22,"*") -> ROB006*
B23: 13 | C23: BRU010 | D23: ZCP | E23: BRUC12 | F23: =VLOOKUP(C23,[9]Dados!B:C,2,0) -> BRU010-BRUNIDORA | G23: =IFERROR(VLOOKUP(C23,#REF!,4,FALSE),"") | H23: =VLOOKUP(C23,Dados!B:AW,11,0) -> 1.26 | I23: =(VLOOKUP(C23,Dados!B:AW,48,0)) -> Fase de Degradação | J23: Não há | K23: =IFERROR((VLOOKUP(C23,Dados!B:AW,44,0)),0) -> 0 | L23: =IFERROR((VLOOKUP(C23,Dados!B:AW,45,0)),0) -> 0 | M23: =IFERROR((VLOOKUP(C23,Dados!B:AW,43,0)),0) -> 0 | N23: =IFERROR((VLOOKUP(C23,Dados!B:AW,47,0)),0) -> 0 | O23: =IF(AND(J23="Parcial",N23>0,H23>1),-1,IF(AND(J23="Parcial",N23>0,H23<1.1),1,IF(AND(J23="Parcial",N23<0,H23>1.09),-1,IF(J23="Total",-1,IF(H23>1.09,1,2))))) -> 1 | P23: =IF(G23="",0,IF(H23>G23,-1,1)) -> 0 | AC23: 2 | AD23: 2 | AE23: 1 | AH23: BRU036 | AI23: =CONCATENATE(AH23,"*") -> BRU036*
B24: 66 | C24: BRU073 | D24: ZCP | E24: BRUC12 | F24: BRU073-BRUNIDORA | G24: =IFERROR(VLOOKUP(C24,#REF!,4,FALSE),"") | H24: =VLOOKUP(C24,Dados!B:AW,11,0) -> 1.07 | I24: =(VLOOKUP(C24,Dados!B:AW,48,0)) -> Fase de Vida Útil | J24: Não há | K24: =IFERROR((VLOOKUP(C24,Dados!B:AW,44,0)),0) -> 0 | L24: =IFERROR((VLOOKUP(C24,Dados!B:AW,45,0)),0) -> 0 | M24: =IFERROR((VLOOKUP(C24,Dados!B:AW,43,0)),0) -> 0 | N24: =IFERROR((VLOOKUP(C24,Dados!B:AW,47,0)),0) -> 0 | O24: =IF(AND(J24="Parcial",N24>0,H24>1),-1,IF(AND(J24="Parcial",N24>0,H24<1.1),1,IF(AND(J24="Parcial",N24<0,H24>1.09),-1,IF(J24="Total",-1,IF(H24>1.09,1,2))))) -> 2 | P24: =IF(G24="",0,IF(H24>G24,-1,1)) -> 0 | AC24: -1 | AD24: -1 | AE24: -1 | AH24: INJ004 | AI24: =CONCATENATE(AH24,"*") -> INJ004*
B25: 24 | C25: BRU031 | D25: ZCP | E25: BRUC13 | F25: =VLOOKUP(C25,[9]Dados!B:C,2,0) -> BRU031-BRUNIDORA | G25: =IFERROR(VLOOKUP(C25,#REF!,4,FALSE),"") | H25: =VLOOKUP(C25,Dados!B:AW,11,0) -> 1.4 | I25: =(VLOOKUP(C25,Dados!B:AW,48,0)) -> Fase de Degradação | J25: Não há | K25: =IFERROR((VLOOKUP(C25,Dados!B:AW,44,0)),0) -> 0 | L25: =IFERROR((VLOOKUP(C25,Dados!B:AW,45,0)),0) -> 0 | M25: =IFERROR((VLOOKUP(C25,Dados!B:AW,43,0)),0) -> 0 | N25: =IFERROR((VLOOKUP(C25,Dados!B:AW,47,0)),0) -> 0 | O25: =IF(AND(J25="Parcial",N25>0,H25>1),-1,IF(AND(J25="Parcial",N25>0,H25<1.1),1,IF(AND(J25="Parcial",N25<0,H25>1.09),-1,IF(J25="Total",-1,IF(H25>1.09,1,2))))) -> 1 | P25: =IF(G25="",0,IF(H25>G25,-1,1)) -> 0 | AC25: 2 | AD25: 2 | AE25: 1 | AH25: CAB110 | AI25: =CONCATENATE(AH25,"*") -> CAB110*
B26: 25 | C26: BRU032 | D26: ZCP | E26: BRUC13 | F26: =VLOOKUP(C26,[9]Dados!B:C,2,0) -> BRU032-BRUNIDORA | G26: =IFERROR(VLOOKUP(C26,#REF!,4,FALSE),"") | H26: =VLOOKUP(C26,Dados!B:AW,11,0) -> 1.97 | I26: =(VLOOKUP(C26,Dados!B:AW,48,0)) -> Fase de Degradação | J26: Total | K26: =IFERROR((VLOOKUP(C26,Dados!B:AW,44,0)),0) -> 0 | L26: =IFERROR((VLOOKUP(C26,Dados!B:AW,45,0)),0) -> 0 | M26: =IFERROR((VLOOKUP(C26,Dados!B:AW,43,0)),0) -> 0 | N26: =IFERROR((VLOOKUP(C26,Dados!B:AW,47,0)),0) -> 0 | O26: =IF(AND(J26="Parcial",N26>0,H26>1),-1,IF(AND(J26="Parcial",N26>0,H26<1.1),1,IF(AND(J26="Parcial",N26<0,H26>1.09),-1,IF(J26="Total",-1,IF(H26>1.09,1,2))))) -> -1 | P26: =IF(G26="",0,IF(H26>G26,-1,1)) -> 0 | AC26: -1 | AD26: -1 | AE26: -1 | AH26: ROB039 | AI26: =CONCATENATE(AH26,"*") -> ROB039*
B27: 12 | C27: BRU009 | D27: ZCP | E27: BRUC14 | F27: BRU009-BRUNIDORA | G27: =IFERROR(VLOOKUP(C27,#REF!,4,FALSE),"") | H27: =VLOOKUP(C27,Dados!B:AW,11,0) -> 1.35 | I27: =(VLOOKUP(C27,Dados!B:AW,48,0)) -> Fase de Degradação | J27: Não há | K27: =IFERROR((VLOOKUP(C27,Dados!B:AW,44,0)),0) -> 0 | L27: =IFERROR((VLOOKUP(C27,Dados!B:AW,45,0)),0) -> 0 | M27: =IFERROR((VLOOKUP(C27,Dados!B:AW,43,0)),0) -> 0 | N27: =IFERROR((VLOOKUP(C27,Dados!B:AW,47,0)),0) -> 0 | O27: =IF(AND(J27="Parcial",N27>0,H27>1),-1,IF(AND(J27="Parcial",N27>0,H27<1.1),1,IF(AND(J27="Parcial",N27<0,H27>1.09),-1,IF(J27="Total",-1,IF(H27>1.09,1,2))))) -> 1 | P27: =IF(G27="",0,IF(H27>G27,-1,1)) -> 0 | AC27: 2 | AD27: 2 | AE27: 1 | AH27: ROB017 | AI27: =CONCATENATE(AH27,"*") -> ROB017*
B28: 50 | C28: BRU057 | D28: ZCP | E28: BRUC14 | F28: BRU057-BRUNIDORA | G28: =IFERROR(VLOOKUP(C28,#REF!,4,FALSE),"") | H28: =VLOOKUP(C28,Dados!B:AW,11,0) -> 1.13 | I28: =(VLOOKUP(C28,Dados!B:AW,48,0)) -> Fase de Degradação | K28: =IFERROR((VLOOKUP(C28,Dados!B:AW,44,0)),0) -> 0 | L28: =IFERROR((VLOOKUP(C28,Dados!B:AW,45,0)),0) -> 0 | M28: =IFERROR((VLOOKUP(C28,Dados!B:AW,43,0)),0) -> 0 | N28: =IFERROR((VLOOKUP(C28,Dados!B:AW,47,0)),0) -> 0 | O28: =IF(AND(J28="Parcial",N28>0,H28>1),-1,IF(AND(J28="Parcial",N28>0,H28<1.1),1,IF(AND(J28="Parcial",N28<0,H28>1.09),-1,IF(J28="Total",-1,IF(H28>1.09,1,2))))) -> 1 | P28: =IF(G28="",0,IF(H28>G28,-1,1)) -> 0 | AC28: -1 | AD28: -1 | AE28: -1 | AH28: PRE010 | AI28: =CONCATENATE(AH28,"*") -> PRE010*
B29: 28 | C29: BRU035 | D29: ZCP | E29: BRUC15 | F29: =VLOOKUP(C29,[9]Dados!B:C,2,0) -> BRU035-BRUNIDORA | G29: =IFERROR(VLOOKUP(C29,#REF!,4,FALSE),"") | H29: =VLOOKUP(C29,Dados!B:AW,11,0) -> 2.4 | I29: =(VLOOKUP(C29,Dados!B:AW,48,0)) -> Fase de Degradação | J29: Total | K29: =IFERROR((VLOOKUP(C29,Dados!B:AW,44,0)),0) -> 0 | L29: =IFERROR((VLOOKUP(C29,Dados!B:AW,45,0)),0) -> 0 | M29: =IFERROR((VLOOKUP(C29,Dados!B:AW,43,0)),0) -> 0 | N29: =IFERROR((VLOOKUP(C29,Dados!B:AW,47,0)),0) -> 0 | O29: =IF(AND(J29="Parcial",N29>0,H29>1),-1,IF(AND(J29="Parcial",N29>0,H29<1.1),1,IF(AND(J29="Parcial",N29<0,H29>1.09),-1,IF(J29="Total",-1,IF(H29>1.09,1,2))))) -> -1 | P29: =IF(G29="",0,IF(H29>G29,-1,1)) -> 0 | AC29: 2 | AD29: 2 | AE29: 1 | AH29: ROB005 | AI29: =CONCATENATE(AH29,"*") -> ROB005*
B30: 29 | C30: BRU036 | D30: ZCP | E30: BRUC15 | F30: =VLOOKUP(C30,[9]Dados!B:C,2,0) -> BRU036-BRUNIDORA | G30: =IFERROR(VLOOKUP(C30,#REF!,4,FALSE),"") | H30: =VLOOKUP(C30,Dados!B:AW,11,0) -> 2.08 | I30: =(VLOOKUP(C30,Dados!B:AW,48,0)) -> Fase de Degradação | J30: Não há | K30: =IFERROR((VLOOKUP(C30,Dados!B:AW,44,0)),0) -> 0 | L30: =IFERROR((VLOOKUP(C30,Dados!B:AW,45,0)),0) -> 0 | M30: =IFERROR((VLOOKUP(C30,Dados!B:AW,43,0)),0) -> 0 | N30: =IFERROR((VLOOKUP(C30,Dados!B:AW,47,0)),0) -> 0 | O30: =IF(AND(J30="Parcial",N30>0,H30>1),-1,IF(AND(J30="Parcial",N30>0,H30<1.1),1,IF(AND(J30="Parcial",N30<0,H30>1.09),-1,IF(J30="Total",-1,IF(H30>1.09,1,2))))) -> 1 | P30: =IF(G30="",0,IF(H30>G30,-1,1)) -> 0 | AC30: -1 | AD30: -1 | AE30: -1 | AH30: TOR020 | AI30: =CONCATENATE(AH30,"*") -> TOR020*
B31: 30 | C31: BRU037 | D31: ZCP | E31: BRUC16 | F31: =VLOOKUP(C31,[9]Dados!B:C,2,0) -> BRU037-BRUNIDORA | G31: =IFERROR(VLOOKUP(C31,#REF!,4,FALSE),"") | H31: =VLOOKUP(C31,Dados!B:AW,11,0) -> 2.59 | I31: =(VLOOKUP(C31,Dados!B:AW,48,0)) -> Fase de Degradação | J31: Não há | K31: =IFERROR((VLOOKUP(C31,Dados!B:AW,44,0)),0) -> 0 | L31: =IFERROR((VLOOKUP(C31,Dados!B:AW,45,0)),0) -> 0 | M31: =IFERROR((VLOOKUP(C31,Dados!B:AW,43,0)),0) -> 0 | N31: =IFERROR((VLOOKUP(C31,Dados!B:AW,47,0)),0) -> 0 | O31: =IF(AND(J31="Parcial",N31>0,H31>1),-1,IF(AND(J31="Parcial",N31>0,H31<1.1),1,IF(AND(J31="Parcial",N31<0,H31>1.09),-1,IF(J31="Total",-1,IF(H31>1.09,1,2))))) -> 1 | P31: =IF(G31="",0,IF(H31>G31,-1,1)) -> 0 | AC31: 2 | AD31: 2 | AE31: 1 | AH31: TOR021 | AI31: =CONCATENATE(AH31,"*") -> TOR021*
B32: 31 | C32: BRU038 | D32: ZCP | E32: BRUC16 | F32: BRU038-BRUNIDORA | G32: =IFERROR(VLOOKUP(C32,#REF!,4,FALSE),"") | H32: =VLOOKUP(C32,Dados!B:AW,11,0) -> 1.82 | I32: =(VLOOKUP(C32,Dados!B:AW,48,0)) -> Fase de Degradação | J32: Não há | K32: =IFERROR((VLOOKUP(C32,Dados!B:AW,44,0)),0) -> 0 | L32: =IFERROR((VLOOKUP(C32,Dados!B:AW,45,0)),0) -> 0 | M32: =IFERROR((VLOOKUP(C32,Dados!B:AW,43,0)),0) -> 0 | N32: =IFERROR((VLOOKUP(C32,Dados!B:AW,47,0)),0) -> 0 | O32: =IF(AND(J32="Parcial",N32>0,H32>1),-1,IF(AND(J32="Parcial",N32>0,H32<1.1),1,IF(AND(J32="Parcial",N32<0,H32>1.09),-1,IF(J32="Total",-1,IF(H32>1.09,1,2))))) -> 1 | P32: =IF(G32="",0,IF(H32>G32,-1,1)) -> 0 | AC32: -1 | AD32: -1 | AE32: -1 | AH32: TOR028 | AI32: =CONCATENATE(AH32,"*") -> TOR028*
B33: 32 | C33: BRU039 | D33: ZCP | E33: BRUC17 | F33: BRU039-BRUNIDORA | G33: =IFERROR(VLOOKUP(C33,#REF!,4,FALSE),"") | H33: =VLOOKUP(C33,Dados!B:AW,11,0) -> 2.34 | I33: =(VLOOKUP(C33,Dados!B:AW,48,0)) -> Fase de Degradação | J33: Total | K33: =IFERROR((VLOOKUP(C33,Dados!B:AW,44,0)),0) -> 0 | L33: =IFERROR((VLOOKUP(C33,Dados!B:AW,45,0)),0) -> 0 | M33: =IFERROR((VLOOKUP(C33,Dados!B:AW,43,0)),0) -> 0 | N33: =IFERROR((VLOOKUP(C33,Dados!B:AW,47,0)),0) -> 0 | O33: =IF(AND(J33="Parcial",N33>0,H33>1),-1,IF(AND(J33="Parcial",N33>0,H33<1.1),1,IF(AND(J33="Parcial",N33<0,H33>1.09),-1,IF(J33="Total",-1,IF(H33>1.09,1,2))))) -> -1 | P33: =IF(G33="",0,IF(H33>G33,-1,1)) -> 0 | AC33: -1 | AD33: -1 | AE33: -1 | AH33: CEN058 | AI33: =CONCATENATE(AH33,"*") -> CEN058*
B34: 33 | C34: BRU040 | D34: ZCP | E34: BRUC17 | F34: BRU040-BRUNIDORA | G34: =IFERROR(VLOOKUP(C34,#REF!,4,FALSE),"") | H34: =VLOOKUP(C34,Dados!B:AW,11,0) -> 1.39 | I34: =(VLOOKUP(C34,Dados!B:AW,48,0)) -> Fase de Degradação | J34: Não há | K34: =IFERROR((VLOOKUP(C34,Dados!B:AW,44,0)),0) -> 0 | L34: =IFERROR((VLOOKUP(C34,Dados!B:AW,45,0)),0) -> 0 | M34: =IFERROR((VLOOKUP(C34,Dados!B:AW,43,0)),0) -> 0 | N34: =IFERROR((VLOOKUP(C34,Dados!B:AW,47,0)),0) -> 0 | O34: =IF(AND(J34="Parcial",N34>0,H34>1),-1,IF(AND(J34="Parcial",N34>0,H34<1.1),1,IF(AND(J34="Parcial",N34<0,H34>1.09),-1,IF(J34="Total",-1,IF(H34>1.09,1,2))))) -> 1 | P34: =IF(G34="",0,IF(H34>G34,-1,1)) -> 0 | AC34: 2 | AD34: 2 | AE34: 1 | AH34: ROB010 | AI34: =CONCATENATE(AH34,"*") -> ROB010*
B35: 35 | C35: BRU042 | D35: ZCP | E35: BRUC18 | F35: BRU042-BRUNIDORA | G35: =IFERROR(VLOOKUP(C35,#REF!,4,FALSE),"") | H35: =VLOOKUP(C35,Dados!B:AW,11,0) -> 1.22 | I35: =(VLOOKUP(C35,Dados!B:AW,48,0)) -> Fase de Degradação | J35: Total | K35: =IFERROR((VLOOKUP(C35,Dados!B:AW,44,0)),0) -> 0 | L35: =IFERROR((VLOOKUP(C35,Dados!B:AW,45,0)),0) -> 0 | M35: =IFERROR((VLOOKUP(C35,Dados!B:AW,43,0)),0) -> 0 | N35: =IFERROR((VLOOKUP(C35,Dados!B:AW,47,0)),0) -> 0 | O35: =IF(AND(J35="Parcial",N35>0,H35>1),-1,IF(AND(J35="Parcial",N35>0,H35<1.1),1,IF(AND(J35="Parcial",N35<0,H35>1.09),-1,IF(J35="Total",-1,IF(H35>1.09,1,2))))) -> -1 | P35: =IF(G35="",0,IF(H35>G35,-1,1)) -> 0 | AC35: -1 | AD35: -1 | AE35: -1 | AH35: ROB037 | AI35: =CONCATENATE(AH35,"*") -> ROB037*
B36: 36 | C36: BRU043 | D36: ZCP | E36: BRUC18 | F36: BRU043-BRUNIDORA | G36: =IFERROR(VLOOKUP(C36,#REF!,4,FALSE),"") | H36: =VLOOKUP(C36,Dados!B:AW,11,0) -> 1.35 | I36: =(VLOOKUP(C36,Dados!B:AW,48,0)) -> Fase de Degradação | J36: Não há | K36: =IFERROR((VLOOKUP(C36,Dados!B:AW,44,0)),0) -> 0 | L36: =IFERROR((VLOOKUP(C36,Dados!B:AW,45,0)),0) -> 0 | M36: =IFERROR((VLOOKUP(C36,Dados!B:AW,43,0)),0) -> 0 | N36: =IFERROR((VLOOKUP(C36,Dados!B:AW,47,0)),0) -> 0 | O36: =IF(AND(J36="Parcial",N36>0,H36>1),-1,IF(AND(J36="Parcial",N36>0,H36<1.1),1,IF(AND(J36="Parcial",N36<0,H36>1.09),-1,IF(J36="Total",-1,IF(H36>1.09,1,2))))) -> 1 | P36: =IF(G36="",0,IF(H36>G36,-1,1)) -> 0 | AC36: 2 | AD36: 2 | AE36: 1 | AH36: CEN064 | AI36: =CONCATENATE(AH36,"*") -> CEN064*
B37: 37 | C37: BRU044 | D37: ZCP | E37: BRUC19 | F37: =VLOOKUP(C37,[9]Dados!B:C,2,0) -> BRU044-BRUNIDORA | G37: =IFERROR(VLOOKUP(C37,#REF!,4,FALSE),"") | H37: =VLOOKUP(C37,Dados!B:AW,11,0) -> 1.39 | I37: =(VLOOKUP(C37,Dados!B:AW,48,0)) -> Fase de Degradação | J37: Não há | K37: =IFERROR((VLOOKUP(C37,Dados!B:AW,44,0)),0) -> 0 | L37: =IFERROR((VLOOKUP(C37,Dados!B:AW,45,0)),0) -> 0 | M37: =IFERROR((VLOOKUP(C37,Dados!B:AW,43,0)),0) -> 0 | N37: =IFERROR((VLOOKUP(C37,Dados!B:AW,47,0)),0) -> 0 | O37: =IF(AND(J37="Parcial",N37>0,H37>1),-1,IF(AND(J37="Parcial",N37>0,H37<1.1),1,IF(AND(J37="Parcial",N37<0,H37>1.09),-1,IF(J37="Total",-1,IF(H37>1.09,1,2))))) -> 1 | P37: =IF(G37="",0,IF(H37>G37,-1,1)) -> 0 | AC37: -1 | AD37: -1 | AE37: -1 | AH37: TOR027 | AI37: =CONCATENATE(AH37,"*") -> TOR027*
B38: 38 | C38: BRU045 | D38: ZCP | E38: BRUC19 | F38: =VLOOKUP(C38,[9]Dados!B:C,2,0) -> BRU045-BRUNIDORA | G38: =IFERROR(VLOOKUP(C38,#REF!,4,FALSE),"") | H38: =VLOOKUP(C38,Dados!B:AW,11,0) -> 1.79 | I38: =(VLOOKUP(C38,Dados!B:AW,48,0)) -> Fase de Degradação | J38: Não há | K38: =IFERROR((VLOOKUP(C38,Dados!B:AW,44,0)),0) -> 0 | L38: =IFERROR((VLOOKUP(C38,Dados!B:AW,45,0)),0) -> 0 | M38: =IFERROR((VLOOKUP(C38,Dados!B:AW,43,0)),0) -> 0 | N38: =IFERROR((VLOOKUP(C38,Dados!B:AW,47,0)),0) -> 0 | O38: =IF(AND(J38="Parcial",N38>0,H38>1),-1,IF(AND(J38="Parcial",N38>0,H38<1.1),1,IF(AND(J38="Parcial",N38<0,H38>1.09),-1,IF(J38="Total",-1,IF(H38>1.09,1,2))))) -> 1 | P38: =IF(G38="",0,IF(H38>G38,-1,1)) -> 0 | AC38: 2 | AD38: 2 | AE38: 1 | AH38: CEN094 | AI38: =CONCATENATE(AH38,"*") -> CEN094*
B39: 39 | C39: BRU046 | D39: ZCP | E39: BRUC20 | F39: =VLOOKUP(C39,[9]Dados!B:C,2,0) -> BRU046-BRUNIDORA | G39: =IFERROR(VLOOKUP(C39,#REF!,4,FALSE),"") | H39: =VLOOKUP(C39,Dados!B:AW,11,0) -> 1.69 | I39: =(VLOOKUP(C39,Dados!B:AW,48,0)) -> Fase de Degradação | J39: Total | K39: =IFERROR((VLOOKUP(C39,Dados!B:AW,44,0)),0) -> 0 | L39: =IFERROR((VLOOKUP(C39,Dados!B:AW,45,0)),0) -> 0 | M39: =IFERROR((VLOOKUP(C39,Dados!B:AW,43,0)),0) -> 0 | N39: =IFERROR((VLOOKUP(C39,Dados!B:AW,47,0)),0) -> 0 | O39: =IF(AND(J39="Parcial",N39>0,H39>1),-1,IF(AND(J39="Parcial",N39>0,H39<1.1),1,IF(AND(J39="Parcial",N39<0,H39>1.09),-1,IF(J39="Total",-1,IF(H39>1.09,1,2))))) -> -1 | P39: =IF(G39="",0,IF(H39>G39,-1,1)) -> 0 | AC39: -1 | AD39: -1 | AE39: -1 | AH39: BRU045 | AI39: =CONCATENATE(AH39,"*") -> BRU045*
B40: 40 | C40: BRU047 | D40: ZCP | E40: BRUC20 | F40: BRU047-BRUNIDORA | G40: =IFERROR(VLOOKUP(C40,#REF!,4,FALSE),"") | H40: =VLOOKUP(C40,Dados!B:AW,11,0) -> 1.05 | I40: =(VLOOKUP(C40,Dados!B:AW,48,0)) -> Fase de Vida Útil | J40: Não há | K40: =IFERROR((VLOOKUP(C40,Dados!B:AW,44,0)),0) -> 0 | L40: =IFERROR((VLOOKUP(C40,Dados!B:AW,45,0)),0) -> 0 | M40: =IFERROR((VLOOKUP(C40,Dados!B:AW,43,0)),0) -> 0 | N40: =IFERROR((VLOOKUP(C40,Dados!B:AW,47,0)),0) -> 0 | O40: =IF(AND(J40="Parcial",N40>0,H40>1),-1,IF(AND(J40="Parcial",N40>0,H40<1.1),1,IF(AND(J40="Parcial",N40<0,H40>1.09),-1,IF(J40="Total",-1,IF(H40>1.09,1,2))))) -> 2 | P40: =IF(G40="",0,IF(H40>G40,-1,1)) -> 0 | AC40: -1 | AD40: -1 | AE40: -1 | AH40: CEN065 | AI40: =CONCATENATE(AH40,"*") -> CEN065*
B41: 41 | C41: BRU048 | D41: ZCP | E41: BRUC21 | F41: BRU048-BRUNIDORA | G41: =IFERROR(VLOOKUP(C41,#REF!,4,FALSE),"") | H41: =VLOOKUP(C41,Dados!B:AW,11,0) -> 1.06 | I41: =(VLOOKUP(C41,Dados!B:AW,48,0)) -> Fase de Vida Útil | J41: Não há | K41: =IFERROR((VLOOKUP(C41,Dados!B:AW,44,0)),0) -> 0 | L41: =IFERROR((VLOOKUP(C41,Dados!B:AW,45,0)),0) -> 0 | M41: =IFERROR((VLOOKUP(C41,Dados!B:AW,43,0)),0) -> 0 | N41: =IFERROR((VLOOKUP(C41,Dados!B:AW,47,0)),0) -> 0 | O41: =IF(AND(J41="Parcial",N41>0,H41>1),-1,IF(AND(J41="Parcial",N41>0,H41<1.1),1,IF(AND(J41="Parcial",N41<0,H41>1.09),-1,IF(J41="Total",-1,IF(H41>1.09,1,2))))) -> 2 | P41: =IF(G41="",0,IF(H41>G41,-1,1)) -> 0 | AC41: 2 | AD41: 2 | AE41: 1 | AH41: TOR025 | AI41: =CONCATENATE(AH41,"*") -> TOR025*
...

Sheet Dados
A1: ID | B1: TAG | C1: Denominação | D1: Nº SAP | E1: Local Instalação | F1: Centro Custo | G1: Imobilizado | H1: Ano Aquisição | I1: Valor de Aquisição Atual | J1: Valor Residual Atual | K1: Custo de Manut. Total | L1: Beta | M1: Tempo de Missão (Horas Trab Ano) | N1: Tempo Total | O1: Qtd Falhas Totais | P1: Falha Ano 1 | Q1: Falha Ano 2 | R1: Falha Ano 3 | S1: Falha Ano 4 | T1: Falha Ano 5 | U1: Falha Ano 6 | V1: Falha Ano 7 | W1: Custo Esperado por Corretiva | X1: Custo Esperado Preventiva Mensal | Y1: Taxa | Z1: Acréscimo Aquisição | AA1: Red. Custo Manut. | AB1: 0 - Atual | AC1: 1 | AD1: 2 | AE1: 3 | AF1: 4 | AG1: 5 | AH1: 6 | AI1: 7 | AJ1: 0 - Novo | AK1: 12 | AL1: 23 | AM1: 34 | AN1: 45 | AO1: 56 | AP1: 67 | AQ1: 78 | AR1: POTENCIAL GANHO | AS1: Custo Esperado Atual | AT1: Custo Esperado Novo | AU1: Profit | AV1: ROI | AW1: Fase | AX1: Mini Fab | AY1: OBS | AZ1: OK | BE1: Realizado LCC | BF1: =(COUNTIF($AZ:$AZ,"X")/COUNT(Tabela1[ID])) -> 0.93704246
A2: 1 | B2: APL001 | C2: APL001-APLAINADORA MAXITEC | D2: 10000457 | E2: BR01-MOT-SAB-TRTTRM-APL001 | F2: 2511 | G2: 2200100100 | H2: 2004 | I2: 70007.01 | J2: 0 | K2: 811304.92 | L2: 1.27 | M2: 5020 | N2: 195391 | O2: 420 | P2: =IFERROR(VLOOKUP(Tabela1[[#This Row],[TAG]],#REF!,14,FALSE),"") | Q2: =P2+P2 -> #VALUE! | R2: =Q2+P2 -> #VALUE! | S2: =R2+P2 -> #VALUE! | T2: =S2+P2 -> #VALUE! | U2: =T2+P2 -> #VALUE! | V2: =U2+P2 -> #VALUE! | W2: 966.83 | X2: 4873.49 | Y2: 0.1 | Z2: =IF(Tabela1[[#This Row],[Ano Aquisição]]=2023,0,IFERROR(VLOOKUP(H2,inflação!$F:$H,3,FALSE),"")) -> 1.1001 | AA2: 0.8 | AB2: =I2*-1 -> -70007.01 | AC2: =-(((P2*$W2)+($X2*12))*((1+$Y2)^AC$1)) -> #VALUE! | AD2: =-((((Q2-P2)*$W2)+($X2*12))*((1+$Y2)^AD$1)) -> #VALUE! | AE2: =-((((R2-Q2)*$W2)+($X2*12))*((1+$Y2)^AE$1)) -> #VALUE! | AF2: =-((((S2-R2)*$W2)+($X2*12))*((1+$Y2)^AF$1)) -> #VALUE! | AG2: =-((((T2-S2)*$W2)+($X2*12))*((1+$Y2)^AG$1)) -> #VALUE! | AH2: =-((((U2-T2)*$W2)+($X2*12))*((1+$Y2)^AH$1)) -> #VALUE! | AI2: =-((((V2-U2)*$W2)+($X2*12))*((1+$Y2)^AI$1)) -> #VALUE! | AJ2: =-(I2*(1+Z2)) -> -147021.72 | AK2: =AC2*(1-$AA2) -> #VALUE! | AL2: =AD2*(1-$AA2) -> #VALUE! | AM2: =AE2*(1-$AA2) -> #VALUE! | AN2: =AF2*(1-$AA2) -> #VALUE! | AO2: =AG2*(1-$AA2) -> #VALUE! | AP2: =AH2*(1-$AA2) -> #VALUE! | AQ2: =AI2*(1-$AA2) -> #VALUE! | AR2: =(NPV(Y2,AK2,AL2,AM2,AN2,AO2,AP2,AQ2)+(SUM(AJ2,(J2*-1))))-(NPV(Y2,AC2,AD2,AE2,AF2,AG2,AH2,AI2)) -> #VALUE! | AS2: =SUM(AC2:AI2) -> #VALUE! | AT2: =SUM(AK2:AQ2) -> #VALUE! | AU2: =(((AVERAGE(AC2:AI2)/1000)-(AVERAGE(AK2:AQ2)/1000))+(((AJ2/1000)*-1)/7)+((J2/1000)/7))*-1 -> #VALUE! | AV2: =AU2/(((J2/1000)+((AJ2*-1)/1000))) -> #VALUE! | AW2: =IF(L2>1.1,"Fase de Degradação",IF(L2<1,"Confiabilidade em Crescimento","Fase de Vida Útil")) -> Fase de Degradação | AX2: =VLOOKUP(D2,#REF!,5,FALSE) -> #REF! | AZ2: X | BB2: =IFERROR(VLOOKUP(Tabela1[[#This Row],[Denominação]],[10]Planilha1!$A:$B,2,FALSE),"") -> 811304.92
A3: 2 | B3: BAL003 | C3: BAL003-BALANCEADORA | D3: 10003740 | E3: BR01-CIL-UCI-VOLANT-BAL003 | F3: 4548 | G3: - | H3: 2008 | I3: 184344.2 | J3: 0 | K3: 135505.04 | L3: 0.75 | M3: 4433 | N3: 116075 | O3: 175 | P3: =IFERROR(VLOOKUP(Tabela1[[#This Row],[TAG]],#REF!,14,FALSE),"") | Q3: =P3+P3 -> #VALUE! | R3: =Q3+P3 -> #VALUE! | S3: =R3+P3 -> #VALUE! | T3: =S3+P3 -> #VALUE! | U3: =T3+P3 -> #VALUE! | V3: =U3+P3 -> #VALUE! | W3: 257.32 | X3: 312.04 | Y3: 0.1 | Z3: =IF(Tabela1[[#This Row],[Ano Aquisição]]=2023,0,IFERROR(VLOOKUP(H3,inflação!$F:$H,3,FALSE),"")) -> 0.8912 | AA3: 0.8 | AB3: =I3*-1 -> -184344.2 | AC3: =-(((P3*$W3)+($X3*12))*((1+$Y3)^AC$1)) -> #VALUE! | AD3: =-((((Q3-P3)*$W3)+($X3*12))*((1+$Y3)^AD$1)) -> #VALUE! | AE3: =-((((R3-Q3)*$W3)+($X3*12))*((1+$Y3)^AE$1)) -> #VALUE! | AF3: =-((((S3-R3)*$W3)+($X3*12))*((1+$Y3)^AF$1)) -> #VALUE! | AG3: =-((((T3-S3)*$W3)+($X3*12))*((1+$Y3)^AG$1)) -> #VALUE! | AH3: =-((((U3-T3)*$W3)+($X3*12))*((1+$Y3)^AH$1)) -> #VALUE! | AI3: =-((((V3-U3)*$W3)+($X3*12))*((1+$Y3)^AI$1)) -> #VALUE! | AJ3: =-(I3*(1+Z3)) -> -348631.75 | AK3: =AC3*(1-$AA3) -> #VALUE! | AL3: =AD3*(1-$AA3) -> #VALUE! | AM3: =AE3*(1-$AA3) -> #VALUE! | AN3: =AF3*(1-$AA3) -> #VALUE! | AO3: =AG3*(1-$AA3) -> #VALUE! | AP3: =AH3*(1-$AA3) -> #VALUE! | AQ3: =AI3*(1-$AA3) -> #VALUE! | AR3: =(NPV(Y3,AK3,AL3,AM3,AN3,AO3,AP3,AQ3)+(SUM(AJ3,(J3*-1))))-(NPV(Y3,AC3,AD3,AE3,AF3,AG3,AH3,AI3)) -> #VALUE! | AS3: =SUM(AC3:AI3) -> #VALUE! | AT3: =SUM(AK3:AQ3) -> #VALUE! | AU3: =(((AVERAGE(AC3:AI3)/1000)-(AVERAGE(AK3:AQ3)/1000))+(((AJ3/1000)*-1)/7)+((J3/1000)/7))*-1 -> #VALUE! | AV3: =AU3/(((J3/1000)+((AJ3*-1)/1000))) -> #VALUE! | AW3: =IF(L3>1.1,"Fase de Degradação",IF(L3<1,"Confiabilidade em Crescimento","Fase de Vida Útil")) -> Confiabilidade em Crescimento | AX3: =VLOOKUP(D3,#REF!,5,FALSE) -> #REF! | AZ3: X | BB3: =IFERROR(VLOOKUP(Tabela1[[#This Row],[Denominação]],[10]Planilha1!$A:$B,2,FALSE),"") -> 135505.04
A4: 3 | B4: BAL004 | C4: BAL004-BALANCEADORA | D4: 10006290 | E4: BR01-CIL-UCI-VOLANT-BAL004 | F4: 4548 | G4: 36407 | H4: 2009 | I4: 184344.2 | J4: 0 | K4: 284121.64 | L4: 1.12 | M4: 4433 | N4: 71239 | O4: 253 | P4: =IFERROR(VLOOKUP(Tabela1[[#This Row],[TAG]],#REF!,14,FALSE),"") | Q4: =P4+P4 -> #VALUE! | R4: =Q4+P4 -> #VALUE! | S4: =R4+P4 -> #VALUE! | T4: =S4+P4 -> #VALUE! | U4: =T4+P4 -> #VALUE! | V4: =U4+P4 -> #VALUE! | W4: 412.47 | X4: 831.28 | Y4: 0.1 | Z4: =IF(Tabela1[[#This Row],[Ano Aquisição]]=2023,0,IFERROR(VLOOKUP(H4,inflação!$F:$H,3,FALSE),"")) -> 0.8322 | AA4: 0.8 | AB4: =I4*-1 -> -184344.2 | AC4: =-(((P4*$W4)+($X4*12))*((1+$Y4)^AC$1)) -> #VALUE! | AD4: =-((((Q4-P4)*$W4)+($X4*12))*((1+$Y4)^AD$1)) -> #VALUE! | AE4: =-((((R4-Q4)*$W4)+($X4*12))*((1+$Y4)^AE$1)) -> #VALUE! | AF4: =-((((S4-R4)*$W4)+($X4*12))*((1+$Y4)^AF$1)) -> #VALUE! | AG4: =-((((T4-S4)*$W4)+($X4*12))*((1+$Y4)^AG$1)) -> #VALUE! | AH4: =-((((U4-T4)*$W4)+($X4*12))*((1+$Y4)^AH$1)) -> #VALUE! | AI4: =-((((V4-U4)*$W4)+($X4*12))*((1+$Y4)^AI$1)) -> #VALUE! | AJ4: =-(I4*(1+Z4)) -> -337755.44 | AK4: =AC4*(1-$AA4) -> #VALUE! | AL4: =AD4*(1-$AA4) -> #VALUE! | AM4: =AE4*(1-$AA4) -> #VALUE! | AN4: =AF4*(1-$AA4) -> #VALUE! | AO4: =AG4*(1-$AA4) -> #VALUE! | AP4: =AH4*(1-$AA4) -> #VALUE! | AQ4: =AI4*(1-$AA4) -> #VALUE! | AR4: =(NPV(Y4,AK4,AL4,AM4,AN4,AO4,AP4,AQ4)+(SUM(AJ4,(J4*-1))))-(NPV(Y4,AC4,AD4,AE4,AF4,AG4,AH4,AI4)) -> #VALUE! | AS4: =SUM(AC4:AI4) -> #VALUE! | AT4: =SUM(AK4:AQ4) -> #VALUE! | AU4: =(((AVERAGE(AC4:AI4)/1000)-(AVERAGE(AK4:AQ4)/1000))+(((AJ4/1000)*-1)/7)+((J4/1000)/7))*-1 -> #VALUE! | AV4: =AU4/(((J4/1000)+((AJ4*-1)/1000))) -> #VALUE! | AW4: =IF(L4>1.1,"Fase de Degradação",IF(L4<1,"Confiabilidade em Crescimento","Fase de Vida Útil")) -> Fase de Degradação | AX4: =VLOOKUP(D4,#REF!,5,FALSE) -> #REF! | AZ4: X | BB4: =IFERROR(VLOOKUP(Tabela1[[#This Row],[Denominação]],[10]Planilha1!$A:$B,2,FALSE),"") -> 284121.64
A5: 4 | B5: BAL006 | C5: BAL006-BALANCEADORA | D5: 10006845 | E5: BR01-CIL-UCI-VOLANT-BAL006 | F5: 4548 | G5: 46611 | H5: 2016 | I5: 560982.64 | J5: 206356 | K5: 2171.91 | L5: 1.12 | M5: 4433 | N5: 39853 | O5: 146 | P5: =IFERROR(VLOOKUP(Tabela1[[#This Row],[TAG]],#REF!,14,FALSE),"") | Q5: =P5+P5 -> #VALUE! | R5: =Q5+P5 -> #VALUE! | S5: =R5+P5 -> #VALUE! | T5: =S5+P5 -> #VALUE! | U5: =T5+P5 -> #VALUE! | V5: =U5+P5 -> #VALUE! | W5: 513.03 | X5: 433.37 | Y5: 0.1 | Z5: =IF(Tabela1[[#This Row],[Ano Aquisição]]=2023,0,IFERROR(VLOOKUP(H5,inflação!$F:$H,3,FALSE),"")) -> 0.3767 | AA5: 0.8 | AB5: =I5*-1 -> -560982.64 | AC5: =-(((P5*$W5)+($X5*12))*((1+$Y5)^AC$1)) -> #VALUE! | AD5: =-((((Q5-P5)*$W5)+($X5*12))*((1+$Y5)^AD$1)) -> #VALUE! | AE5: =-((((R5-Q5)*$W5)+($X5*12))*((1+$Y5)^AE$1)) -> #VALUE! | AF5: =-((((S5-R5)*$W5)+($X5*12))*((1+$Y5)^AF$1)) -> #VALUE! | AG5: =-((((T5-S5)*$W5)+($X5*12))*((1+$Y5)^AG$1)) -> #VALUE! | AH5: =-((((U5-T5)*$W5)+($X5*12))*((1+$Y5)^AH$1)) -> #VALUE! | AI5: =-((((V5-U5)*$W5)+($X5*12))*((1+$Y5)^AI$1)) -> #VALUE! | AJ5: =-(I5*(1+Z5)) -> -772304.8 | AK5: =AC5*(1-$AA5) -> #VALUE! | AL5: =AD5*(1-$AA5) -> #VALUE! | AM5: =AE5*(1-$AA5) -> #VALUE! | AN5: =AF5*(1-$AA5) -> #VALUE! | AO5: =AG5*(1-$AA5) -> #VALUE! | AP5: =AH5*(1-$AA5) -> #VALUE! | AQ5: =AI5*(1-$AA5) -> #VALUE! | AR5: =(NPV(Y5,AK5,AL5,AM5,AN5,AO5,AP5,AQ5)+(SUM(AJ5,(J5*-1))))-(NPV(Y5,AC5,AD5,AE5,AF5,AG5,AH5,AI5)) -> #VALUE! | AS5: =SUM(AC5:AI5) -> #VALUE! | AT5: =SUM(AK5:AQ5) -> #VALUE! | AU5: =(((AVERAGE(AC5:AI5)/1000)-(AVERAGE(AK5:AQ5)/1000))+(((AJ5/1000)*-1)/7)+((J5/1000)/7))*-1 -> #VALUE! | AV5: =AU5/(((J5/1000)+((AJ5*-1)/1000))) -> #VALUE! | AW5: =IF(L5>1.1,"Fase de Degradação",IF(L5<1,"Confiabilidade em Crescimento","Fase de Vida Útil")) -> Fase de Degradação | AX5: =VLOOKUP(D5,#REF!,5,FALSE) -> #REF! | AZ5: X | BB5: =IFERROR(VLOOKUP(Tabela1[[#This Row],[Denominação]],[10]Planilha1!$A:$B,2,FALSE),"") -> 2171.91
A6: 5 | B6: BAL007 | C6: BAL007-BALANCEADORA | D6: 10006406 | E6: BR01-CIL-UCI-VOLANT-BAL007 | F6: 4548 | G6: 53931 | H6: 2021 | I6: 792392.34 | J6: 690145 | K6: 144168.47 | L6: 0.89 | M6: 4433 | N6: 57501 | O6: 169 | P6: =IFERROR(VLOOKUP(Tabela1[[#This Row],[TAG]],#REF!,14,FALSE),"") | Q6: =P6+P6 -> #VALUE! | R6: =Q6+P6 -> #VALUE! | S6: =R6+P6 -> #VALUE! | T6: =S6+P6 -> #VALUE! | U6: =T6+P6 -> #VALUE! | V6: =U6+P6 -> #VALUE! | W6: 217.83 | X6: 490.13 | Y6: 0.1 | Z6: =IF(Tabela1[[#This Row],[Ano Aquisição]]=2023,0,IFERROR(VLOOKUP(H6,inflação!$F:$H,3,FALSE),"")) -> 0.1585 | AA6: 0.8 | AB6: =I6*-1 -> -792392.34 | AC6: =-(((P6*$W6)+($X6*12))*((1+$Y6)^AC$1)) -> #VALUE! | AD6: =-((((Q6-P6)*$W6)+($X6*12))*((1+$Y6)^AD$1)) -> #VALUE! | AE6: =-((((R6-Q6)*$W6)+($X6*12))*((1+$Y6)^AE$1)) -> #VALUE! | AF6: =-((((S6-R6)*$W6)+($X6*12))*((1+$Y6)^AF$1)) -> #VALUE! | AG6: =-((((T6-S6)*$W6)+($X6*12))*((1+$Y6)^AG$1)) -> #VALUE! | AH6: =-((((U6-T6)*$W6)+($X6*12))*((1+$Y6)^AH$1)) -> #VALUE! | AI6: =-((((V6-U6)*$W6)+($X6*12))*((1+$Y6)^AI$1)) -> #VALUE! | AJ6: =-(I6*(1+Z6)) -> -917986.53 | AK6: =AC6*(1-$AA6) -> #VALUE! | AL6: =AD6*(1-$AA6) -> #VALUE! | AM6: =AE6*(1-$AA6) -> #VALUE! | AN6: =AF6*(1-$AA6) -> #VALUE! | AO6: =AG6*(1-$AA6) -> #VALUE! | AP6: =AH6*(1-$AA6) -> #VALUE! | AQ6: =AI6*(1-$AA6) -> #VALUE! | AR6: =(NPV(Y6,AK6,AL6,AM6,AN6,AO6,AP6,AQ6)+(SUM(AJ6,(J6*-1))))-(NPV(Y6,AC6,AD6,AE6,AF6,AG6,AH6,AI6)) -> #VALUE! | AS6: =SUM(AC6:AI6) -> #VALUE! | AT6: =SUM(AK6:AQ6) -> #VALUE! | AU6: =(((AVERAGE(AC6:AI6)/1000)-(AVERAGE(AK6:AQ6)/1000))+(((AJ6/1000)*-1)/7)+((J6/1000)/7))*-1 -> #VALUE! | AV6: =AU6/(((J6/1000)+((AJ6*-1)/1000))) -> #VALUE! | AW6: =IF(L6>1.1,"Fase de Degradação",IF(L6<1,"Confiabilidade em Crescimento","Fase de Vida Útil")) -> Confiabilidade em Crescimento | AX6: =VLOOKUP(D6,#REF!,5,FALSE) -> #REF! | AZ6: X | BB6: =IFERROR(VLOOKUP(Tabela1[[#This Row],[Denominação]],[10]Planilha1!$A:$B,2,FALSE),"") -> 144168.47
A7: 6 | B7: BAL008 | C7: BAL008-BALANCEADORA | D7: 10006719 | E7: BR01-CIL-UCI-VOLANT-BAL008 | F7: 4548 | G7: 55614 | H7: 2021 | I7: 748548.06 | J7: 673691 | K7: 11740.33 | L7: 0.92 | M7: 4433 | N7: 10039 | O7: 18 | P7: =IFERROR(VLOOKUP(Tabela1[[#This Row],[TAG]],#REF!,14,FALSE),"") | Q7: =P7+P7 -> #VALUE! | R7: =Q7+P7 -> #VALUE! | S7: =R7+P7 -> #VALUE! | T7: =S7+P7 -> #VALUE! | U7: =T7+P7 -> #VALUE! | V7: =U7+P7 -> #VALUE! | W7: 354.77 | X7: 553.08 | Y7: 0.1 | Z7: =IF(Tabela1[[#This Row],[Ano Aquisição]]=2023,0,IFERROR(VLOOKUP(H7,inflação!$F:$H,3,FALSE),"")) -> 0.1585 | AA7: 0.8 | AB7: =I7*-1 -> -748548.06 | AC7: =-(((P7*$W7)+($X7*12))*((1+$Y7)^AC$1)) -> #VALUE! | AD7: =-((((Q7-P7)*$W7)+($X7*12))*((1+$Y7)^AD$1)) -> #VALUE! | AE7: =-((((R7-Q7)*$W7)+($X7*12))*((1+$Y7)^AE$1)) -> #VALUE! | AF7: =-((((S7-R7)*$W7)+($X7*12))*((1+$Y7)^AF$1)) -> #VALUE! | AG7: =-((((T7-S7)*$W7)+($X7*12))*((1+$Y7)^AG$1)) -> #VALUE! | AH7: =-((((U7-T7)*$W7)+($X7*12))*((1+$Y7)^AH$1)) -> #VALUE! | AI7: =-((((V7-U7)*$W7)+($X7*12))*((1+$Y7)^AI$1)) -> #VALUE! | AJ7: =-(I7*(1+Z7)) -> -867192.93 | AK7: =AC7*(1-$AA7) -> #VALUE! | AL7: =AD7*(1-$AA7) -> #VALUE! | AM7: =AE7*(1-$AA7) -> #VALUE! | AN7: =AF7*(1-$AA7) -> #VALUE! | AO7: =AG7*(1-$AA7) -> #VALUE! | AP7: =AH7*(1-$AA7) -> #VALUE! | AQ7: =AI7*(1-$AA7) -> #VALUE! | AR7: =(NPV(Y7,AK7,AL7,AM7,AN7,AO7,AP7,AQ7)+(SUM(AJ7,(J7*-1))))-(NPV(Y7,AC7,AD7,AE7,AF7,AG7,AH7,AI7)) -> #VALUE! | AS7: =SUM(AC7:AI7) -> #VALUE! | AT7: =SUM(AK7:AQ7) -> #VALUE! | AU7: =(((AVERAGE(AC7:AI7)/1000)-(AVERAGE(AK7:AQ7)/1000))+(((AJ7/1000)*-1)/7)+((J7/1000)/7))*-1 -> #VALUE! | AV7: =AU7/(((J7/1000)+((AJ7*-1)/1000))) -> #VALUE! | AW7: =IF(L7>1.1,"Fase de Degradação",IF(L7<1,"Confiabilidade em Crescimento","Fase de Vida Útil")) -> Confiabilidade em Crescimento | AX7: =VLOOKUP(D7,#REF!,5,FALSE) -> #REF! | AZ7: X | BB7: =IFERROR(VLOOKUP(Tabela1[[#This Row],[Denominação]],[10]Planilha1!$A:$B,2,FALSE),"") -> 11740.33
A8: 7 | B8: BAL009 | C8: BAL009-BALANCEADORA | D8: 10006732 | E8: BR01-MOT-UMG-MISCEL-BAL009 | F8: 2376 | G8: 55185 | H8: 2021 | I8: 315956.73 | J8: 278098 | K8: 2960.93 | L8: 0.93 | M8: 3854 | N8: 9849 | O8: 3 | P8: =IFERROR(VLOOKUP(Tabela1[[#This Row],[TAG]],#REF!,14,FALSE),"") | Q8: =P8+P8 -> #VALUE! | R8: =Q8+P8 -> #VALUE! | S8: =R8+P8 -> #VALUE! | T8: =S8+P8 -> #VALUE! | U8: =T8+P8 -> #VALUE! | V8: =U8+P8 -> #VALUE! | W8: 627.23 | X8: 467.39 | Y8: 0.1 | Z8: =IF(Tabela1[[#This Row],[Ano Aquisição]]=2023,0,IFERROR(VLOOKUP(H8,inflação!$F:$H,3,FALSE),"")) -> 0.1585 | AA8: 0.8 | AB8: =I8*-1 -> -315956.73 | AC8: =-(((P8*$W8)+($X8*12))*((1+$Y8)^AC$1)) -> #VALUE! | AD8: =-((((Q8-P8)*$W8)+($X8*12))*((1+$Y8)^AD$1)) -> #VALUE! | AE8: =-((((R8-Q8)*$W8)+($X8*12))*((1+$Y8)^AE$1)) -> #VALUE! | AF8: =-((((S8-R8)*$W8)+($X8*12))*((1+$Y8)^AF$1)) -> #VALUE! | AG8: =-((((T8-S8)*$W8)+($X8*12))*((1+$Y8)^AG$1)) -> #VALUE! | AH8: =-((((U8-T8)*$W8)+($X8*12))*((1+$Y8)^AH$1)) -> #VALUE! | AI8: =-((((V8-U8)*$W8)+($X8*12))*((1+$Y8)^AI$1)) -> #VALUE! | AJ8: =-(I8*(1+Z8)) -> -366035.87 | AK8: =AC8*(1-$AA8) -> #VALUE! | AL8: =AD8*(1-$AA8) -> #VALUE! | AM8: =AE8*(1-$AA8) -> #VALUE! | AN8: =AF8*(1-$AA8) -> #VALUE! | AO8: =AG8*(1-$AA8) -> #VALUE! | AP8: =AH8*(1-$AA8) -> #VALUE! | AQ8: =AI8*(1-$AA8) -> #VALUE! | AR8: =(NPV(Y8,AK8,AL8,AM8,AN8,AO8,AP8,AQ8)+(SUM(AJ8,(J8*-1))))-(NPV(Y8,AC8,AD8,AE8,AF8,AG8,AH8,AI8)) -> #VALUE! | AS8: =SUM(AC8:AI8) -> #VALUE! | AT8: =SUM(AK8:AQ8) -> #VALUE! | AU8: =(((AVERAGE(AC8:AI8)/1000)-(AVERAGE(AK8:AQ8)/1000))+(((AJ8/1000)*-1)/7)+((J8/1000)/7))*-1 -> #VALUE! | AV8: =AU8/(((J8/1000)+((AJ8*-1)/1000))) -> #VALUE! | AW8: =IF(L8>1.1,"Fase de Degradação",IF(L8<1,"Confiabilidade em Crescimento","Fase de Vida Útil")) -> Confiabilidade em Crescimento | AX8: =VLOOKUP(D8,#REF!,5,FALSE) -> #REF! | AZ8: X | BB8: =IFERROR(VLOOKUP(Tabela1[[#This Row],[Denominação]],[10]Planilha1!$A:$B,2,FALSE),"") -> 2960.93
A9: 8 | B9: BRU002 | C9: BRU002-BRUNIDORA | D9: 10000309 | E9: BR01-MOT-VIR-USIDUR-BRU002 | F9: 3316 | G9: 800200200 | H9: 1986 | I9: 230561.52 | J9: 0 | K9: 252551.51 | L9: 1.15 | M9: 4392 | N9: 197421 | O9: 309 | P9: =IFERROR(VLOOKUP(Tabela1[[#This Row],[TAG]],#REF!,14,FALSE),"") | Q9: =P9+P9 -> #VALUE! | R9: =Q9+P9 -> #VALUE! | S9: =R9+P9 -> #VALUE! | T9: =S9+P9 -> #VALUE! | U9: =T9+P9 -> #VALUE! | V9: =U9+P9 -> #VALUE! | W9: 692.35 | X9: 1510.85 | Y9: 0.1 | Z9: =IF(Tabela1[[#This Row],[Ano Aquisição]]=2023,0,IFERROR(VLOOKUP(H9,inflação!$F:$H,3,FALSE),"")) -> 2.3433462 | AA9: 0.8 | AB9: =I9*-1 -> -230561.52 | AC9: =-(((P9*$W9)+($X9*12))*((1+$Y9)^AC$1)) -> #VALUE! | AD9: =-((((Q9-P9)*$W9)+($X9*12))*((1+$Y9)^AD$1)) -> #VALUE! | AE9: =-((((R9-Q9)*$W9)+($X9*12))*((1+$Y9)^AE$1)) -> #VALUE! | AF9: =-((((S9-R9)*$W9)+($X9*12))*((1+$Y9)^AF$1)) -> #VALUE! | AG9: =-((((T9-S9)*$W9)+($X9*12))*((1+$Y9)^AG$1)) -> #VALUE! | AH9: =-((((U9-T9)*$W9)+($X9*12))*((1+$Y9)^AH$1)) -> #VALUE! | AI9: =-((((V9-U9)*$W9)+($X9*12))*((1+$Y9)^AI$1)) -> #VALUE! | AJ9: =-(I9*(1+Z9)) -> -770846.97 | AK9: =AC9*(1-$AA9) -> #VALUE! | AL9: =AD9*(1-$AA9) -> #VALUE! | AM9: =AE9*(1-$AA9) -> #VALUE! | AN9: =AF9*(1-$AA9) -> #VALUE! | AO9: =AG9*(1-$AA9) -> #VALUE! | AP9: =AH9*(1-$AA9) -> #VALUE! | AQ9: =AI9*(1-$AA9) -> #VALUE! | AR9: =(NPV(Y9,AK9,AL9,AM9,AN9,AO9,AP9,AQ9)+(SUM(AJ9,(J9*-1))))-(NPV(Y9,AC9,AD9,AE9,AF9,AG9,AH9,AI9)) -> #VALUE! | AS9: =SUM(AC9:AI9) -> #VALUE! | AT9: =SUM(AK9:AQ9) -> #VALUE! | AU9: =(((AVERAGE(AC9:AI9)/1000)-(AVERAGE(AK9:AQ9)/1000))+(((AJ9/1000)*-1)/7)+((J9/1000)/7))*-1 -> #VALUE! | AV9: =AU9/(((J9/1000)+((AJ9*-1)/1000))) -> #VALUE! | AW9: =IF(L9>1.1,"Fase de Degradação",IF(L9<1,"Confiabilidade em Crescimento","Fase de Vida Útil")) -> Fase de Degradação | AX9: =VLOOKUP(D9,#REF!,5,FALSE) -> #REF! | AZ9: X | BB9: =IFERROR(VLOOKUP(Tabela1[[#This Row],[Denominação]],[10]Planilha1!$A:$B,2,FALSE),"") -> 252551.51
A10: 9 | B10: BRU003 | C10: BRU003-BRUNIDORA | D10: 10000313 | E10: BR01-MOT-VIR-LBIELA-BRU003 | F10: 3337 | G10: 800100200 | H10: 1977 | I10: 151187.09 | J10: 0 | K10: 276100.33 | L10: 1.11 | M10: 4392 | N10: 198333 | O10: 353 | P10: =IFERROR(VLOOKUP(Tabela1[[#This Row],[TAG]],#REF!,14,FALSE),"") | Q10: =P10+P10 -> #VALUE! | R10: =Q10+P10 -> #VALUE! | S10: =R10+P10 -> #VALUE! | T10: =S10+P10 -> #VALUE! | U10: =T10+P10 -> #VALUE! | V10: =U10+P10 -> #VALUE! | W10: 594.92 | X10: 1515.77 | Y10: 0.1 | Z10: =IF(Tabela1[[#This Row],[Ano Aquisição]]=2023,0,IFERROR(VLOOKUP(H10,inflação!$F:$H,3,FALSE),"")) -> 2.9147077 | AA10: 0.8 | AB10: =I10*-1 -> -151187.09 | AC10: =-(((P10*$W10)+($X10*12))*((1+$Y10)^AC$1)) -> #VALUE! | AD10: =-((((Q10-P10)*$W10)+($X10*12))*((1+$Y10)^AD$1)) -> #VALUE! | AE10: =-((((R10-Q10)*$W10)+($X10*12))*((1+$Y10)^AE$1)) -> #VALUE! | AF10: =-((((S10-R10)*$W10)+($X10*12))*((1+$Y10)^AF$1)) -> #VALUE! | AG10: =-((((T10-S10)*$W10)+($X10*12))*((1+$Y10)^AG$1)) -> #VALUE! | AH10: =-((((U10-T10)*$W10)+($X10*12))*((1+$Y10)^AH$1)) -> #VALUE! | AI10: =-((((V10-U10)*$W10)+($X10*12))*((1+$Y10)^AI$1)) -> #VALUE! | AJ10: =-(I10*(1+Z10)) -> -591853.26 | AK10: =AC10*(1-$AA10) -> #VALUE! | AL10: =AD10*(1-$AA10) -> #VALUE! | AM10: =AE10*(1-$AA10) -> #VALUE! | AN10: =AF10*(1-$AA10) -> #VALUE! | AO10: =AG10*(1-$AA10) -> #VALUE! | AP10: =AH10*(1-$AA10) -> #VALUE! | AQ10: =AI10*(1-$AA10) -> #VALUE! | AR10: =(NPV(Y10,AK10,AL10,AM10,AN10,AO10,AP10,AQ10)+(SUM(AJ10,(J10*-1))))-(NPV(Y10,AC10,AD10,AE10,AF10,AG10,AH10,AI10)) -> #VALUE! | AS10: =SUM(AC10:AI10) -> #VALUE! | AT10: =SUM(AK10:AQ10) -> #VALUE! | AU10: =(((AVERAGE(AC10:AI10)/1000)-(AVERAGE(AK10:AQ10)/1000))+(((AJ10/1000)*-1)/7)+((J10/1000)/7))*-1 -> #VALUE! | AV10: =AU10/(((J10/1000)+((AJ10*-1)/1000))) -> #VALUE! | AW10: =IF(L10>1.1,"Fase de Degradação",IF(L10<1,"Confiabilidade em Crescimento","Fase de Vida Útil")) -> Fase de Degradação | AX10: =VLOOKUP(D10,#REF!,5,FALSE) -> #REF! | AZ10: X | BB10: =IFERROR(VLOOKUP(Tabela1[[#This Row],[Denominação]],[10]Planilha1!$A:$B,2,FALSE),"") -> 276100.33
A11: 10 | B11: BRU004 | C11: BRU004-BRUNIDORA | D11: 10000317 | E11: BR01-MOT-VIR-LBIELA-BRU004 | F11: 3336 | G11: 800100100 | H11: 1985 | I11: 230561.52 | J11: 0 | K11: 1133969.9 | L11: 1.35 | M11: 4392 | N11: 198895 | O11: 1336 | P11: =IFERROR(VLOOKUP(Tabela1[[#This Row],[TAG]],#REF!,14,FALSE),"") | Q11: =P11+P11 -> #VALUE! | R11: =Q11+P11 -> #VALUE! | S11: =R11+P11 -> #VALUE! | T11: =S11+P11 -> #VALUE! | U11: =T11+P11 -> #VALUE! | V11: =U11+P11 -> #VALUE! | W11: 555.67 | X11: 5146.48 | Y11: 0.1 | Z11: =IF(Tabela1[[#This Row],[Ano Aquisição]]=2023,0,IFERROR(VLOOKUP(H11,inflação!$F:$H,3,FALSE),"")) -> 2.4068308 | AA11: 0.8 | AB11: =I11*-1 -> -230561.52 | AC11: =-(((P11*$W11)+($X11*12))*((1+$Y11)^AC$1)) -> #VALUE! | AD11: =-((((Q11-P11)*$W11)+($X11*12))*((1+$Y11)^AD$1)) -> #VALUE! | AE11: =-((((R11-Q11)*$W11)+($X11*12))*((1+$Y11)^AE$1)) -> #VALUE! | AF11: =-((((S11-R11)*$W11)+($X11*12))*((1+$Y11)^AF$1)) -> #VALUE! | AG11: =-((((T11-S11)*$W11)+($X11*12))*((1+$Y11)^AG$1)) -> #VALUE! | AH11: =-((((U11-T11)*$W11)+($X11*12))*((1+$Y11)^AH$1)) -> #VALUE! | AI11: =-((((V11-U11)*$W11)+($X11*12))*((1+$Y11)^AI$1)) -> #VALUE! | AJ11: =-(I11*(1+Z11)) -> -785484.08 | AK11: =AC11*(1-$AA11) -> #VALUE! | AL11: =AD11*(1-$AA11) -> #VALUE! | AM11: =AE11*(1-$AA11) -> #VALUE! | AN11: =AF11*(1-$AA11) -> #VALUE! | AO11: =AG11*(1-$AA11) -> #VALUE! | AP11: =AH11*(1-$AA11) -> #VALUE! | AQ11: =AI11*(1-$AA11) -> #VALUE! | AR11: =(NPV(Y11,AK11,AL11,AM11,AN11,AO11,AP11,AQ11)+(SUM(AJ11,(J11*-1))))-(NPV(Y11,AC11,AD11,AE11,AF11,AG11,AH11,AI11)) -> #VALUE! | AS11: =SUM(AC11:AI11) -> #VALUE! | AT11: =SUM(AK11:AQ11) -> #VALUE! | AU11: =(((AVERAGE(AC11:AI11)/1000)-(AVERAGE(AK11:AQ11)/1000))+(((AJ11/1000)*-1)/7)+((J11/1000)/7))*-1 -> #VALUE! | AV11: =AU11/(((J11/1000)+((AJ11*-1)/1000))) -> #VALUE! | AW11: =IF(L11>1.1,"Fase de Degradação",IF(L11<1,"Confiabilidade em Crescimento","Fase de Vida Útil")) -> Fase de Degradação | AX11: =VLOOKUP(D11,#REF!,5,FALSE) -> #REF! | AZ11: X | BB11: =IFERROR(VLOOKUP(Tabela1[[#This Row],[Denominação]],[10]Planilha1!$A:$B,2,FALSE),"") -> 1133969.9
A12: 11 | B12: BRU008 | C12: BRU008-BRUNIDORA | D12: 10000155 | E12: BR01-CIL-UCI-BRUNI1-BRUC02 | F12: 4529 | G12: Não encontrado | H12: 1997 | I12: 93300.55 | J12: 0 | K12: 225074.07 | L12: 0.95 | M12: 4464 | N12: 195980 | O12: 338 | P12: =IFERROR(VLOOKUP(Tabela1[[#This Row],[TAG]],#REF!,14,FALSE),"") | Q12: =P12+P12 -> #VALUE! | R12: =Q12+P12 -> #VALUE! | S12: =R12+P12 -> #VALUE! | T12: =S12+P12 -> #VALUE! | U12: =T12+P12 -> #VALUE! | V12: =U12+P12 -> #VALUE! | W12: 259.8 | X12: 397.37 | Y12: 0.1 | Z12: =IF(Tabela1[[#This Row],[Ano Aquisição]]=2023,0,IFERROR(VLOOKUP(H12,inflação!$F:$H,3,FALSE),"")) -> 1.6129 | AA12: 0.8 | AB12: =I12*-1 -> -93300.55 | AC12: =-(((P12*$W12)+($X12*12))*((1+$Y12)^AC$1)) -> #VALUE! | AD12: =-((((Q12-P12)*$W12)+($X12*12))*((1+$Y12)^AD$1)) -> #VALUE! | AE12: =-((((R12-Q12)*$W12)+($X12*12))*((1+$Y12)^AE$1)) -> #VALUE! | AF12: =-((((S12-R12)*$W12)+($X12*12))*((1+$Y12)^AF$1)) -> #VALUE! | AG12: =-((((T12-S12)*$W12)+($X12*12))*((1+$Y12)^AG$1)) -> #VALUE! | AH12: =-((((U12-T12)*$W12)+($X12*12))*((1+$Y12)^AH$1)) -> #VALUE! | AI12: =-((((V12-U12)*$W12)+($X12*12))*((1+$Y12)^AI$1)) -> #VALUE! | AJ12: =-(I12*(1+Z12)) -> -243785.01 | AK12: =AC12*(1-$AA12) -> #VALUE! | AL12: =AD12*(1-$AA12) -> #VALUE! | AM12: =AE12*(1-$AA12) -> #VALUE! | AN12: =AF12*(1-$AA12) -> #VALUE! | AO12: =AG12*(1-$AA12) -> #VALUE! | AP12: =AH12*(1-$AA12) -> #VALUE! | AQ12: =AI12*(1-$AA12) -> #VALUE! | AR12: =(NPV(Y12,AK12,AL12,AM12,AN12,AO12,AP12,AQ12)+(SUM(AJ12,(J12*-1))))-(NPV(Y12,AC12,AD12,AE12,AF12,AG12,AH12,AI12)) -> #VALUE! | AS12: =SUM(AC12:AI12) -> #VALUE! | AT12: =SUM(AK12:AQ12) -> #VALUE! | AU12: =(((AVERAGE(AC12:AI12)/1000)-(AVERAGE(AK12:AQ12)/1000))+(((AJ12/1000)*-1)/7)+((J12/1000)/7))*-1 -> #VALUE! | AV12: =AU12/(((J12/1000)+((AJ12*-1)/1000))) -> #VALUE! | AW12: =IF(L12>1.1,"Fase de Degradação",IF(L12<1,"Confiabilidade em Crescimento","Fase de Vida Útil")) -> Confiabilidade em Crescimento | AX12: =VLOOKUP(D12,#REF!,5,FALSE) -> #REF! | AZ12: X | BB12: =IFERROR(VLOOKUP(Tabela1[[#This Row],[Denominação]],[10]Planilha1!$A:$B,2,FALSE),"") -> 227581.53
A13: 12 | B13: BRU009 | C13: BRU009-BRUNIDORA | D13: 10000158 | E13: BR01-CIL-UCI-BRUNI1-BRUC14 | F13: 4529 | G13: 20272 | H13: 1997 | I13: 200514.41 | J13: 91692 | K13: 300158.14 | L13: 1.35 | M13: 4364 | N13: 193716 | O13: 360 | P13: =IFERROR(VLOOKUP(Tabela1[[#This Row],[TAG]],#REF!,14,FALSE),"") | Q13: =P13+P13 -> #VALUE! | R13: =Q13+P13 -> #VALUE! | S13: =R13+P13 -> #VALUE! | T13: =S13+P13 -> #VALUE! | U13: =T13+P13 -> #VALUE! | V13: =U13+P13 -> #VALUE! | W13: 729.83 | X13: 729.47 | Y13: 0.1 | Z13: =IF(Tabela1[[#This Row],[Ano Aquisição]]=2023,0,IFERROR(VLOOKUP(H13,inflação!$F:$H,3,FALSE),"")) -> 1.6129 | AA13: 0.8 | AB13: =I13*-1 -> -200514.41 | AC13: =-(((P13*$W13)+($X13*12))*((1+$Y13)^AC$1)) -> #VALUE! | AD13: =-((((Q13-P13)*$W13)+($X13*12))*((1+$Y13)^AD$1)) -> #VALUE! | AE13: =-((((R13-Q13)*$W13)+($X13*12))*((1+$Y13)^AE$1)) -> #VALUE! | AF13: =-((((S13-R13)*$W13)+($X13*12))*((1+$Y13)^AF$1)) -> #VALUE! | AG13: =-((((T13-S13)*$W13)+($X13*12))*((1+$Y13)^AG$1)) -> #VALUE! | AH13: =-((((U13-T13)*$W13)+($X13*12))*((1+$Y13)^AH$1)) -> #VALUE! | AI13: =-((((V13-U13)*$W13)+($X13*12))*((1+$Y13)^AI$1)) -> #VALUE! | AJ13: =-(I13*(1+Z13)) -> -523924.1 | AK13: =AC13*(1-$AA13) -> #VALUE! | AL13: =AD13*(1-$AA13) -> #VALUE! | AM13: =AE13*(1-$AA13) -> #VALUE! | AN13: =AF13*(1-$AA13) -> #VALUE! | AO13: =AG13*(1-$AA13) -> #VALUE! | AP13: =AH13*(1-$AA13) -> #VALUE! | AQ13: =AI13*(1-$AA13) -> #VALUE! | AR13: =(NPV(Y13,AK13,AL13,AM13,AN13,AO13,AP13,AQ13)+(SUM(AJ13,(J13*-1))))-(NPV(Y13,AC13,AD13,AE13,AF13,AG13,AH13,AI13)) -> #VALUE! | AS13: =SUM(AC13:AI13) -> #VALUE! | AT13: =SUM(AK13:AQ13) -> #VALUE! | AU13: =(((AVERAGE(AC13:AI13)/1000)-(AVERAGE(AK13:AQ13)/1000))+(((AJ13/1000)*-1)/7)+((J13/1000)/7))*-1 -> #VALUE! | AV13: =AU13/(((J13/1000)+((AJ13*-1)/1000))) -> #VALUE! | AW13: =IF(L13>1.1,"Fase de Degradação",IF(L13<1,"Confiabilidade em Crescimento","Fase de Vida Útil")) -> Fase de Degradação | AX13: =VLOOKUP(D13,#REF!,5,FALSE) -> #REF! | AZ13: X | BB13: =IFERROR(VLOOKUP(Tabela1[[#This Row],[Denominação]],[10]Planilha1!$A:$B,2,FALSE),"") -> 300158.14
A14: 13 | B14: BRU010 | C14: BRU010-BRUNIDORA | D14: 10000161 | E14: BR01-CIL-UCI-BRUNI2-BRUC12 | F14: 4529 | G14: 20137 | H14: 1997 | I14: 186725.04 | J14: 92275 | K14: 242532.76 | L14: 1.26 | M14: 4344 | N14: 197229 | O14: 383 | P14: =IFERROR(VLOOKUP(Tabela1[[#This Row],[TAG]],#REF!,14,FALSE),"") | Q14: =P14+P14 -> #VALUE! | R14: =Q14+P14 -> #VALUE! | S14: =R14+P14 -> #VALUE! | T14: =S14+P14 -> #VALUE! | U14: =T14+P14 -> #VALUE! | V14: =U14+P14 -> #VALUE! | W14: 212.67 | X14: 301.32 | Y14: 0.1 | Z14: =IF(Tabela1[[#This Row],[Ano Aquisição]]=2023,0,IFERROR(VLOOKUP(H14,inflação!$F:$H,3,FALSE),"")) -> 1.6129 | AA14: 0.8 | AB14: =I14*-1 -> -186725.04 | AC14: =-(((P14*$W14)+($X14*12))*((1+$Y14)^AC$1)) -> #VALUE! | AD14: =-((((Q14-P14)*$W14)+($X14*12))*((1+$Y14)^AD$1)) -> #VALUE! | AE14: =-((((R14-Q14)*$W14)+($X14*12))*((1+$Y14)^AE$1)) -> #VALUE! | AF14: =-((((S14-R14)*$W14)+($X14*12))*((1+$Y14)^AF$1)) -> #VALUE! | AG14: =-((((T14-S14)*$W14)+($X14*12))*((1+$Y14)^AG$1)) -> #VALUE! | AH14: =-((((U14-T14)*$W14)+($X14*12))*((1+$Y14)^AH$1)) -> #VALUE! | AI14: =-((((V14-U14)*$W14)+($X14*12))*((1+$Y14)^AI$1)) -> #VALUE! | AJ14: =-(I14*(1+Z14)) -> -487893.86 | AK14: =AC14*(1-$AA14) -> #VALUE! | AL14: =AD14*(1-$AA14) -> #VALUE! | AM14: =AE14*(1-$AA14) -> #VALUE! | AN14: =AF14*(1-$AA14) -> #VALUE! | AO14: =AG14*(1-$AA14) -> #VALUE! | AP14: =AH14*(1-$AA14) -> #VALUE! | AQ14: =AI14*(1-$AA14) -> #VALUE! | AR14: =(NPV(Y14,AK14,AL14,AM14,AN14,AO14,AP14,AQ14)+(SUM(AJ14,(J14*-1))))-(NPV(Y14,AC14,AD14,AE14,AF14,AG14,AH14,AI14)) -> #VALUE! | AS14: =SUM(AC14:AI14) -> #VALUE! | AT14: =SUM(AK14:AQ14) -> #VALUE! | AU14: =(((AVERAGE(AC14:AI14)/1000)-(AVERAGE(AK14:AQ14)/1000))+(((AJ14/1000)*-1)/7)+((J14/1000)/7))*-1 -> #VALUE! | AV14: =AU14/(((J14/1000)+((AJ14*-1)/1000))) -> #VALUE! | AW14: =IF(L14>1.1,"Fase de Degradação",IF(L14<1,"Confiabilidade em Crescimento","Fase de Vida Útil")) -> Fase de Degradação | AX14: =VLOOKUP(D14,#REF!,5,FALSE) -> #REF! | AZ14: X | BB14: =IFERROR(VLOOKUP(Tabela1[[#This Row],[Denominação]],[10]Planilha1!$A:$B,2,FALSE),"") -> 244315.57
A15: 14 | B15: BRU011 | C15: BRU011-BRUNIDORA | D15: 10000164 | E15: BR01-CIL-UCI-BRUNI2-BRUC12 | F15: 4529 | G15: 20289 | H15: 1997 | I15: 247380.04 | J15: 100505 | K15: 281713.41 | L15: 1.47 | M15: 4221 | N15: 198185 | O15: 532 | P15: =IFERROR(VLOOKUP(Tabela1[[#This Row],[TAG]],#REF!,14,FALSE),"") | Q15: =P15+P15 -> #VALUE! | R15: =Q15+P15 -> #VALUE! | S15: =R15+P15 -> #VALUE! | T15: =S15+P15 -> #VALUE! | U15: =T15+P15 -> #VALUE! | V15: =U15+P15 -> #VALUE! | W15: 721.72 | X15: 1016.82 | Y15: 0.1 | Z15: =IF(Tabela1[[#This Row],[Ano Aquisição]]=2023,0,IFERROR(VLOOKUP(H15,inflação!$F:$H,3,FALSE),"")) -> 1.6129 | AA15: 0.8 | AB15: =I15*-1 -> -247380.04 | AC15: =-(((P15*$W15)+($X15*12))*((1+$Y15)^AC$1)) -> #VALUE! | AD15: =-((((Q15-P15)*$W15)+($X15*12))*((1+$Y15)^AD$1)) -> #VALUE! | AE15: =-((((R15-Q15)*$W15)+($X15*12))*((1+$Y15)^AE$1)) -> #VALUE! | AF15: =-((((S15-R15)*$W15)+($X15*12))*((1+$Y15)^AF$1)) -> #VALUE! | AG15: =-((((T15-S15)*$W15)+($X15*12))*((1+$Y15)^AG$1)) -> #VALUE! | AH15: =-((((U15-T15)*$W15)+($X15*12))*((1+$Y15)^AH$1)) -> #VALUE! | AI15: =-((((V15-U15)*$W15)+($X15*12))*((1+$Y15)^AI$1)) -> #VALUE! | AJ15: =-(I15*(1+Z15)) -> -646379.31 | AK15: =AC15*(1-$AA15) -> #VALUE! | AL15: =AD15*(1-$AA15) -> #VALUE! | AM15: =AE15*(1-$AA15) -> #VALUE! | AN15: =AF15*(1-$AA15) -> #VALUE! | AO15: =AG15*(1-$AA15) -> #VALUE! | AP15: =AH15*(1-$AA15) -> #VALUE! | AQ15: =AI15*(1-$AA15) -> #VALUE! | AR15: =(NPV(Y15,AK15,AL15,AM15,AN15,AO15,AP15,AQ15)+(SUM(AJ15,(J15*-1))))-(NPV(Y15,AC15,AD15,AE15,AF15,AG15,AH15,AI15)) -> #VALUE! | AS15: =SUM(AC15:AI15) -> #VALUE! | AT15: =SUM(AK15:AQ15) -> #VALUE! | AU15: =(((AVERAGE(AC15:AI15)/1000)-(AVERAGE(AK15:AQ15)/1000))+(((AJ15/1000)*-1)/7)+((J15/1000)/7))*-1 -> #VALUE! | AV15: =AU15/(((J15/1000)+((AJ15*-1)/1000))) -> #VALUE! | AW15: =IF(L15>1.1,"Fase de Degradação",IF(L15<1,"Confiabilidade em Crescimento","Fase de Vida Útil")) -> Fase de Degradação | AX15: =VLOOKUP(D15,#REF!,5,FALSE) -> #REF! | AZ15: X | BB15: =IFERROR(VLOOKUP(Tabela1[[#This Row],[Denominação]],[10]Planilha1!$A:$B,2,FALSE),"") -> 281713.41
